<?xml version="1.0" ?>
<!-- =================================================================================== -->
<!-- |    This document was autogenerated by xacro from robot.xacro                    | -->
<!-- |    EDITING THIS FILE BY HAND IS NOT RECOMMENDED                                 | -->
<!-- =================================================================================== -->
<robot name="lion">
  <!-- <xacro:arg name="robot_type" default="lion"/> -->
  <!-- ros_control plugin -->

  <!-- <xacro:include filename="$(find lion_description)/urdf/$(arg robot_type)/const.xacro"/> -->
  <!--Quadruped Model*******************************************************************************************-->
  <link name="base">
    <inertial>
      <origin rpy="0 0 0" xyz="-0.000638750070817345 -0.00672058356158241 -0.00556735378698432"/>
      <mass value="8.286"/>
      <inertia ixx="0.056529" ixy="-0.001107" ixz="-3.045E-05" iyy="0.14156" iyz="-0.0011531" izz="0.17939"/>
    </inertial>
    <visual>
      <origin rpy="0 0 0" xyz="0 0 0"/>
      <geometry>
        <mesh filename="package://lion_description/meshes/base_link.STL"/>
      </geometry>
      <material name="">
        <color rgba="0.792156862745098 0.819607843137255 0.933333333333333 1"/>
      </material>
    </visual>
    <collision>
      <origin rpy="0 0 0" xyz="0 0 0"/>
      <geometry>
        <box size="0.35 0.24 0.14"/>
      </geometry>
    </collision>
  </link>
  <link name="RF_hip">
    <inertial>
      <origin rpy="0 0 0" xyz="-0.0050797 -0.047183 4.172E-05"/>
      <mass value="1.095"/>
      <inertia ixx="0.0010035" ixy="-0.00021789" ixz="1.433E-06" iyy="0.0014762" iyz="1.005E-06" izz="0.0012507"/>
    </inertial>
    <visual>
      <origin rpy="0 0 0" xyz="0 0 0"/>
      <geometry>
        <mesh filename="package://lion_description/meshes/hip_Link.STL"/>
      </geometry>
      <material name="">
        <color rgba="0.79216 0.81961 0.93333 1"/>
      </material>
    </visual>
    <collision>
      <origin rpy="1.5707963267948966 0 0" xyz="0.0 -0.05 0"/>
      <geometry>
        <!-- <box size="0.05 0.03 0.3"/> -->
        <cylinder length="0.06" radius="0.05"/>
      </geometry>
    </collision>
  </link>
  <joint name="RF_HAA" type="revolute">
    <origin rpy="0.0 0.0 0 " xyz="0.2467 -0.09 0"/>
    <parent link="base"/>
    <child link="RF_hip"/>
    <axis xyz="1 0 0"/>
    <limit effort="55" lower="-1.0" upper="1.0" velocity="30"/>
  </joint>
  <link name="RF_thigh">
    <inertial>
      <origin rpy="0 0 0" xyz="-2.7705E-05 -0.089684 -0.23198"/>
      <mass value="1.556"/>
      <inertia ixx="0.015631" ixy="-8.61E-07" ixz="-6.078E-06" iyy="0.016183" iyz="0.0004689" izz="0.0011163"/>
    </inertial>
    <visual>
      <origin rpy="0 0 0" xyz="0 0 0"/>
      <geometry>
        <mesh filename="package://lion_description/meshes/thigh_Link.STL"/>
      </geometry>
      <material name="">
        <color rgba="0.79216 0.81961 0.93333 1"/>
      </material>
    </visual>
    <collision>
      <origin rpy="1.5707963267948966 0 0" xyz="0 -0.09 -0.3"/>
      <geometry>
        <!-- <box size="0.05 0.03 0.3"/> -->
        <cylinder length="0.06" radius="0.05"/>
      </geometry>
    </collision>
  </link>
  <joint name="RF_HFE" type="revolute">
    <origin rpy="0 0.0 0" xyz="0 0 0"/>
    <parent link="RF_hip"/>
    <child link="RF_thigh"/>
    <axis xyz="0 1 0"/>
    <limit effort="55" lower="-3.0" upper="3.0" velocity="30"/>
  </joint>
  <link name="RF_calf">
    <inertial>
      <origin rpy="0 0 0" xyz="2.05E-06 -0.12517 -0.080832"/>
      <mass value="0.233"/>
      <inertia ixx="0.0033053" ixy="-3.64E-07" ixz="4.028E-06" iyy="0.0033126" iyz="-0.00013194" izz="4.3236E-05"/>
    </inertial>
    <visual>
      <origin rpy="0 0 0" xyz="0 0 0"/>
      <geometry>
        <mesh filename="package://lion_description/meshes/shank_Link.STL"/>
      </geometry>
      <material name="">
        <color rgba="0.79216 0.81961 0.93333 1"/>
      </material>
    </visual>
    <collision>
      <origin rpy="0 0 0" xyz="0 -0.119 -0.15"/>
      <geometry>
        <cylinder length="0.2" radius="0.01"/>
      </geometry>
    </collision>
  </link>
  <joint name="RF_KFE" type="revolute">
    <origin rpy="0 0 0" xyz="0 0 -0.3"/>
    <parent link="RF_thigh"/>
    <child link="RF_calf"/>
    <axis xyz="0 1 0"/>
    <limit effort="55" lower="-3.0" upper="-0.5" velocity="30"/>
  </joint>
  <link name="RF_FOOT">
    <contact>
      <friction_anchor/>
      <stiffness value="30000.0"/>
      <damping value="1000.0"/>
      <spinning_friction value="0.3"/>
      <lateral_friction value="3.0"/>
    </contact>
    <inertial>
      <origin rpy="0 0 0" xyz="0.0002617 0.00017365 0.0085579"/>
      <!-- <mass value="0.03946"/> -->
      <mass value="0.01"/>
      <!-- <inertia ixx="1.4527E-05" ixy="-8.5021E-08" ixz="-4.0103E-07" iyy="1.4601E-05" iyz="-2.6548E-07" izz="6.2338E-06"/> -->
      <inertia ixx="0.001983" ixy="0.000245" ixz="0.000013" iyy="0.002103" iyz="0.0000015" izz="0.000408"/>
    </inertial>
    <visual>
      <origin rpy="0 0 0" xyz="0 0 0"/>
      <geometry>
        <mesh filename="package://lion_description/meshes/foot_Link.STL"/>
      </geometry>
      <material name="">
        <color rgba="0.79216 0.81961 0.93333 1"/>
      </material>
    </visual>
    <collision>
      <origin rpy="0 0 0" xyz="0 0 0.002"/>
      <geometry>
        <sphere radius="0.02"/>
      </geometry>
    </collision>
  </link>
  <joint name="JointFR_foot" type="fixed">
    <origin rpy="0 0 0" xyz="0 -0.119 -0.3105"/>
    <parent link="RF_calf"/>
    <child link="RF_FOOT"/>
    <axis xyz="0 0 1"/>
  </joint>
  <link name="LF_hip">
    <inertial>
      <origin rpy="0 0 0" xyz="-0.0050797 -0.047183 4.172E-05"/>
      <!-- <mass value="0.39498"/> -->
      <mass value="1.095"/>
      <inertia ixx="0.0010035" ixy="-0.00021789" ixz="1.433E-06" iyy="0.0014762" iyz="1.005E-06" izz="0.0012507"/>
    </inertial>
    <visual>
      <origin rpy="0 0 0" xyz="0 0 0"/>
      <geometry>
        <mesh filename="package://lion_description/meshes/hip_Link.STL"/>
      </geometry>
      <material name="">
        <color rgba="0.79216 0.81961 0.93333 1"/>
      </material>
    </visual>
    <collision>
      <origin rpy="1.5707963267948966 0 0" xyz="0.0 -0.05 0"/>
      <geometry>
        <!-- <box size="0.05 0.03 0.3"/> -->
        <cylinder length="0.06" radius="0.05"/>
      </geometry>
    </collision>
  </link>
  <joint name="LF_HAA" type="revolute">
    <origin rpy="3.141592653589793 0.0 0 " xyz="0.2467 0.09 0"/>
    <parent link="base"/>
    <child link="LF_hip"/>
    <axis xyz="1 0 0"/>
    <limit effort="55" lower="-1.0" upper="1.0" velocity="30"/>
  </joint>
  <link name="LF_thigh">
    <inertial>
      <origin rpy="0 0 0" xyz="-2.7705E-05 -0.089684 -0.23198"/>
      <mass value="1.556"/>
      <inertia ixx="0.015631" ixy="-8.61E-07" ixz="-6.078E-06" iyy="0.016183" iyz="0.0004689" izz="0.0011163"/>
    </inertial>
    <visual>
      <origin rpy="0 0 0" xyz="0 0 0"/>
      <geometry>
        <mesh filename="package://lion_description/meshes/thigh_Link.STL"/>
      </geometry>
      <material name="">
        <color rgba="0.79216 0.81961 0.93333 1"/>
      </material>
    </visual>
    <collision>
      <origin rpy="1.5707963267948966 0 0" xyz="0 -0.09 -0.3"/>
      <geometry>
        <!-- <box size="0.05 0.03 0.3"/> -->
        <cylinder length="0.06" radius="0.05"/>
      </geometry>
    </collision>
  </link>
  <joint name="LF_HFE" type="revolute">
    <origin rpy="0 3.141592653589793 0" xyz="0 0 0"/>
    <parent link="LF_hip"/>
    <child link="LF_thigh"/>
    <axis xyz="0 -1 0"/>
    <limit effort="55" lower="-3.0" upper="3.0" velocity="30"/>
  </joint>
  <link name="LF_calf">
    <inertial>
      <origin rpy="0 0 0" xyz="2.05E-06 -0.12517 -0.080832"/>
      <mass value="0.233"/>
      <inertia ixx="0.0033053" ixy="-3.64E-07" ixz="4.028E-06" iyy="0.0033126" iyz="-0.00013194" izz="4.3236E-05"/>
    </inertial>
    <visual>
      <origin rpy="0 0 0" xyz="0 0 0"/>
      <geometry>
        <mesh filename="package://lion_description/meshes/shank_Link.STL"/>
      </geometry>
      <material name="">
        <color rgba="0.79216 0.81961 0.93333 1"/>
      </material>
    </visual>
    <collision>
      <origin rpy="0 0 0" xyz="0 -0.119 -0.15"/>
      <geometry>
        <cylinder length="0.2" radius="0.01"/>
      </geometry>
    </collision>
  </link>
  <joint name="LF_KFE" type="revolute">
    <origin rpy="0 0 0" xyz="0 0 -0.3"/>
    <parent link="LF_thigh"/>
    <child link="LF_calf"/>
    <axis xyz="0 -1 0"/>
    <limit effort="55" lower="-3.0" upper="-0.5" velocity="30"/>
  </joint>
  <link name="LF_FOOT">
    <contact>
      <friction_anchor/>
      <stiffness value="30000.0"/>
      <damping value="1000.0"/>
      <spinning_friction value="0.3"/>
      <lateral_friction value="3.0"/>
    </contact>
    <inertial>
      <origin rpy="0 0 0" xyz="0.0002617 0.00017365 0.0085579"/>
      <!-- <mass value="0.03946"/> -->
      <mass value="0.01"/>
      <!-- <inertia ixx="1.4527E-05" ixy="-8.5021E-08" ixz="-4.0103E-07" iyy="1.4601E-05" iyz="-2.6548E-07" izz="6.2338E-06"/> -->
      <inertia ixx="0.001983" ixy="0.000245" ixz="0.000013" iyy="0.002103" iyz="0.0000015" izz="0.000408"/>
    </inertial>
    <visual>
      <origin rpy="0 0 0" xyz="0 0 0"/>
      <geometry>
        <mesh filename="package://lion_description/meshes/foot_Link.STL"/>
      </geometry>
      <material name="">
        <color rgba="0.79216 0.81961 0.93333 1"/>
      </material>
    </visual>
    <collision>
      <origin rpy="0 0 0" xyz="0 0 0.002"/>
      <geometry>
        <sphere radius="0.02"/>
      </geometry>
    </collision>
  </link>
  <joint name="JointFL_foot" type="fixed">
    <origin rpy="0 0 0" xyz="0 -0.119 -0.3105"/>
    <parent link="LF_calf"/>
    <child link="LF_FOOT"/>
    <axis xyz="0 0 1"/>
  </joint>
  <link name="RH_hip">
    <inertial>
      <origin rpy="0 0 0" xyz="-0.0050797 -0.047183 4.172E-05"/>
      <mass value="1.095"/>
      <inertia ixx="0.0010035" ixy="-0.00021789" ixz="1.433E-06" iyy="0.0014762" iyz="1.005E-06" izz="0.0012507"/>
    </inertial>
    <visual>
      <origin rpy="0 0 0" xyz="0 0 0"/>
      <geometry>
        <mesh filename="package://lion_description/meshes/hip_Link.STL"/>
      </geometry>
      <material name="">
        <color rgba="0.79216 0.81961 0.93333 1"/>
      </material>
    </visual>
    <collision>
      <origin rpy="1.5707963267948966 0 0" xyz="0.0 -0.05 0"/>
      <geometry>
        <!-- <box size="0.05 0.03 0.3"/> -->
        <cylinder length="0.06" radius="0.05"/>
      </geometry>
    </collision>
  </link>
  <joint name="RH_HAA" type="revolute">
    <origin rpy="0.0 3.141592653589793 0 " xyz="-0.2467 -0.09 0"/>
    <parent link="base"/>
    <child link="RH_hip"/>
    <axis xyz="-1 0 0"/>
    <limit effort="55" lower="-1.0" upper="1.0" velocity="30"/>
  </joint>
  <link name="RH_thigh">
    <inertial>
      <origin rpy="0 0 0" xyz="-2.7705E-05 -0.089684 -0.23198"/>
      <mass value="1.556"/>
      <inertia ixx="0.015631" ixy="-8.61E-07" ixz="-6.078E-06" iyy="0.016183" iyz="0.0004689" izz="0.0011163"/>
    </inertial>
    <visual>
      <origin rpy="0 0 0" xyz="0 0 0"/>
      <geometry>
        <mesh filename="package://lion_description/meshes/thigh_Link.STL"/>
      </geometry>
      <material name="">
        <color rgba="0.79216 0.81961 0.93333 1"/>
      </material>
    </visual>
    <collision>
      <origin rpy="1.5707963267948966 0 0" xyz="0 -0.09 -0.3"/>
      <geometry>
        <!-- <box size="0.05 0.03 0.3"/> -->
        <cylinder length="0.06" radius="0.05"/>
      </geometry>
    </collision>
  </link>
  <joint name="RH_HFE" type="revolute">
    <origin rpy="0 3.141592653589793 0" xyz="0 0 0"/>
    <parent link="RH_hip"/>
    <child link="RH_thigh"/>
    <axis xyz="0 1 0"/>
    <limit effort="55" lower="-3.0" upper="3.0" velocity="30"/>
  </joint>
  <link name="RH_calf">
    <inertial>
      <origin rpy="0 0 0" xyz="2.05E-06 -0.12517 -0.080832"/>
      <mass value="0.233"/>
      <inertia ixx="0.0033053" ixy="-3.64E-07" ixz="4.028E-06" iyy="0.0033126" iyz="-0.00013194" izz="4.3236E-05"/>
    </inertial>
    <visual>
      <origin rpy="0 0 0" xyz="0 0 0"/>
      <geometry>
        <mesh filename="package://lion_description/meshes/shank_Link.STL"/>
      </geometry>
      <material name="">
        <color rgba="0.79216 0.81961 0.93333 1"/>
      </material>
    </visual>
    <collision>
      <origin rpy="0 0 0" xyz="0 -0.119 -0.15"/>
      <geometry>
        <cylinder length="0.2" radius="0.01"/>
      </geometry>
    </collision>
  </link>
  <joint name="RH_KFE" type="revolute">
    <origin rpy="0 0 0" xyz="0 0 -0.3"/>
    <parent link="RH_thigh"/>
    <child link="RH_calf"/>
    <axis xyz="0 1 0"/>
    <limit effort="55" lower="-3.0" upper="-0.5" velocity="30"/>
  </joint>
  <link name="RH_FOOT">
    <contact>
      <friction_anchor/>
      <stiffness value="30000.0"/>
      <damping value="1000.0"/>
      <spinning_friction value="0.3"/>
      <lateral_friction value="3.0"/>
    </contact>
    <inertial>
      <origin rpy="0 0 0" xyz="0.0002617 0.00017365 0.0085579"/>
      <!-- <mass value="0.03946"/> -->
      <mass value="0.01"/>
      <!-- <inertia ixx="1.4527E-05" ixy="-8.5021E-08" ixz="-4.0103E-07" iyy="1.4601E-05" iyz="-2.6548E-07" izz="6.2338E-06"/> -->
      <inertia ixx="0.001983" ixy="0.000245" ixz="0.000013" iyy="0.002103" iyz="0.0000015" izz="0.000408"/>
    </inertial>
    <visual>
      <origin rpy="0 0 0" xyz="0 0 0"/>
      <geometry>
        <mesh filename="package://lion_description/meshes/foot_Link.STL"/>
      </geometry>
      <material name="">
        <color rgba="0.79216 0.81961 0.93333 1"/>
      </material>
    </visual>
    <collision>
      <origin rpy="0 0 0" xyz="0 0 0.002"/>
      <geometry>
        <sphere radius="0.02"/>
      </geometry>
    </collision>
  </link>
  <joint name="JointHR_foot" type="fixed">
    <origin rpy="0 0 0" xyz="0 -0.119 -0.3105"/>
    <parent link="RH_calf"/>
    <child link="RH_FOOT"/>
    <axis xyz="0 0 1"/>
  </joint>
  <link name="LH_hip">
    <inertial>
      <origin rpy="0 0 0" xyz="-0.0050797 -0.047183 4.172E-05"/>
      <mass value="1.095"/>
      <inertia ixx="0.0010035" ixy="-0.00021789" ixz="1.433E-06" iyy="0.0014762" iyz="1.005E-06" izz="0.0012507"/>
    </inertial>
    <visual>
      <origin rpy="0 0 0" xyz="0 0 0"/>
      <geometry>
        <mesh filename="package://lion_description/meshes/hip_Link.STL"/>
      </geometry>
      <material name="">
        <color rgba="0.79216 0.81961 0.93333 1"/>
      </material>
    </visual>
    <collision>
      <origin rpy="1.5707963267948966 0 0" xyz="0.0 -0.05 0"/>
      <geometry>
        <!-- <box size="0.05 0.03 0.3"/> -->
        <cylinder length="0.06" radius="0.05"/>
      </geometry>
    </collision>
  </link>
  <joint name="LH_HAA" type="revolute">
    <origin rpy="3.141592653589793 3.141592653589793 0 " xyz="-0.2467 0.09 0"/>
    <parent link="base"/>
    <child link="LH_hip"/>
    <axis xyz="-1 0 0"/>
    <limit effort="55" lower="-1.0" upper="1.0" velocity="30"/>
  </joint>
  <link name="LH_thigh">
    <inertial>
      <origin rpy="0 0 0" xyz="-2.7705E-05 -0.089684 -0.23198"/>
      <mass value="1.556"/>
      <inertia ixx="0.015631" ixy="-8.61E-07" ixz="-6.078E-06" iyy="0.016183" iyz="0.0004689" izz="0.0011163"/>
    </inertial>
    <visual>
      <origin rpy="0 0 0" xyz="0 0 0"/>
      <geometry>
        <mesh filename="package://lion_description/meshes/thigh_Link.STL"/>
      </geometry>
      <material name="">
        <color rgba="0.79216 0.81961 0.93333 1"/>
      </material>
    </visual>
    <collision>
      <origin rpy="1.5707963267948966 0 0" xyz="0 -0.09 -0.3"/>
      <geometry>
        <!-- <box size="0.05 0.03 0.3"/> -->
        <cylinder length="0.06" radius="0.05"/>
      </geometry>
    </collision>
  </link>
  <joint name="LH_HFE" type="revolute">
    <origin rpy="0 6.283185307179586 0" xyz="0 0 0"/>
    <parent link="LH_hip"/>
    <child link="LH_thigh"/>
    <axis xyz="0 -1 0"/>
    <limit effort="55" lower="-3.0" upper="3.0" velocity="30"/>
  </joint>
  <link name="LH_calf">
    <inertial>
      <origin rpy="0 0 0" xyz="2.05E-06 -0.12517 -0.080832"/>
      <mass value="0.233"/>
      <inertia ixx="0.0033053" ixy="-3.64E-07" ixz="4.028E-06" iyy="0.0033126" iyz="-0.00013194" izz="4.3236E-05"/>
    </inertial>
    <visual>
      <origin rpy="0 0 0" xyz="0 0 0"/>
      <geometry>
        <mesh filename="package://lion_description/meshes/shank_Link.STL"/>
      </geometry>
      <material name="">
        <color rgba="0.79216 0.81961 0.93333 1"/>
      </material>
    </visual>
    <collision>
      <origin rpy="0 0 0" xyz="0 -0.119 -0.15"/>
      <geometry>
        <cylinder length="0.2" radius="0.01"/>
      </geometry>
    </collision>
  </link>
  <joint name="LH_KFE" type="revolute">
    <origin rpy="0 0 0" xyz="0 0 -0.3"/>
    <parent link="LH_thigh"/>
    <child link="LH_calf"/>
    <axis xyz="0 -1 0"/>
    <limit effort="55" lower="-3.0" upper="-0.5" velocity="30"/>
  </joint>
  <link name="LH_FOOT">
    <contact>
      <friction_anchor/>
      <stiffness value="30000.0"/>
      <damping value="1000.0"/>
      <spinning_friction value="0.3"/>
      <lateral_friction value="3.0"/>
    </contact>
    <inertial>
      <origin rpy="0 0 0" xyz="0.0002617 0.00017365 0.0085579"/>
      <!-- <mass value="0.03946"/> -->
      <mass value="0.01"/>
      <!-- <inertia ixx="1.4527E-05" ixy="-8.5021E-08" ixz="-4.0103E-07" iyy="1.4601E-05" iyz="-2.6548E-07" izz="6.2338E-06"/> -->
      <inertia ixx="0.001983" ixy="0.000245" ixz="0.000013" iyy="0.002103" iyz="0.0000015" izz="0.000408"/>
    </inertial>
    <visual>
      <origin rpy="0 0 0" xyz="0 0 0"/>
      <geometry>
        <mesh filename="package://lion_description/meshes/foot_Link.STL"/>
      </geometry>
      <material name="">
        <color rgba="0.79216 0.81961 0.93333 1"/>
      </material>
    </visual>
    <collision>
      <origin rpy="0 0 0" xyz="0 0 0.002"/>
      <geometry>
        <sphere radius="0.02"/>
      </geometry>
    </collision>
  </link>
  <joint name="JointHL_foot" type="fixed">
    <origin rpy="0 0 0" xyz="0 -0.119 -0.3105"/>
    <parent link="LH_calf"/>
    <child link="LH_FOOT"/>
    <axis xyz="0 0 1"/>
  </joint>
  <!-- Arm Model ********************************************************************************************************  -->
  <link name="arm_base_link">
    <inertial>
      <origin rpy="0 0 0" xyz="-2.655E-05 -0.00013067 0.042361"/>
      <mass value="0.91201"/>
      <inertia ixx="0.00076553" ixy="3.0928E-06" ixz="4.0773E-06" iyy="0.000762" iyz="-3.7031E-06" izz="0.00081713"/>
    </inertial>
    <visual>
      <origin rpy="0 0 0" xyz="0 0 0"/>
      <geometry>
        <mesh filename="package://lion_armed_description/meshes/arm_base_link.STL"/>
      </geometry>
      <material name="">
        <color rgba="0.89804 0.91765 0.92941 1"/>
      </material>
    </visual>
    <collision>
      <origin rpy="0 0 0" xyz="0 0 0.04"/>
      <geometry>
        <cylinder length="0.06" radius="0.045"/>
      </geometry>
    </collision>
  </link>
  <joint name="body_arm" type="fixed">
    <origin rpy="0 0 0" xyz="0.1075 0 0.0635"/>
    <parent link="base"/>
    <child link="arm_base_link"/>
    <axis xyz="0 0 -1"/>
  </joint>
  <link name="shoulder_link">
    <inertial>
      <origin rpy="0 0 0" xyz="4.6648E-05 0.00012015 -0.0013725"/>
      <mass value="1.8076"/>
      <inertia ixx="0.0070637" ixy="-1.1248E-07" ixz="4.2676E-06" iyy="0.0014085" iyz="-1.6705E-06" izz="0.0069672"/>
    </inertial>
    <visual>
      <origin rpy="0 0 0" xyz="0 0 0"/>
      <geometry>
        <mesh filename="package://lion_armed_description/meshes/shoulder_link.STL"/>
      </geometry>
      <material name="">
        <color rgba="0.89804 0.91765 0.92941 1"/>
      </material>
    </visual>
    <collision>
      <origin rpy="1.5707963267948966 0 0" xyz="0 0 0"/>
      <geometry>
        <cylinder length="0.2" radius="0.04"/>
      </geometry>
    </collision>
  </link>
  <joint name="joint1" type="revolute">
    <origin rpy="0 0 0" xyz="0 0 0.128"/>
    <parent link="arm_base_link"/>
    <child link="shoulder_link"/>
    <axis xyz="0 0 -1"/>
    <limit effort="15.0" lower="-2.618" upper="2.618" velocity="20.0"/>
  </joint>
  <link name="upper_arm_link">
    <inertial>
      <origin rpy="0 0 0" xyz="-0.16223 -0.00053457 -9.6145E-14"/>
      <mass value="0.20654"/>
      <inertia ixx="0.00017354" ixy="4.7067E-05" ixz="-8.9112E-16" iyy="0.0023721" iyz="4.6757E-16" izz="0.0023909"/>
    </inertial>
    <visual>
      <origin rpy="0 0 0" xyz="0 0 0"/>
      <geometry>
        <mesh filename="package://lion_armed_description/meshes/upper_arm_link.STL"/>
      </geometry>
      <material name="">
        <color rgba="1 1 1 1"/>
      </material>
    </visual>
    <collision>
      <origin rpy="0 0 0" xyz="-0.17 0 0"/>
      <geometry>
        <box size="0.25 0.045 0.06"/>
      </geometry>
    </collision>
  </link>
  <joint name="joint2" type="revolute">
    <origin rpy="0 0 0" xyz="0 0 0"/>
    <parent link="shoulder_link"/>
    <child link="upper_arm_link"/>
    <axis xyz="0 1 0"/>
    <limit effort="15.0" lower="0" upper="3.665" velocity="20.0"/>
  </joint>
  <link name="elbow_link">
    <inertial>
      <origin rpy="0 0 0" xyz="0.0776630957799923 -5.66684882904192E-06 0.0506455368238795"/>
      <mass value="0.19779615464477"/>
      <inertia ixx="0.000172309779571075" ixy="5.40217940566371E-08" ixz="-0.000202557640418278" iyy="0.000759104610858122" iyz="2.15341009549695E-08" izz="0.000636430285987363"/>
    </inertial>
    <visual>
      <origin rpy="0 0 0" xyz="0 0 0"/>
      <geometry>
        <mesh filename="package://lion_armed_description/meshes/elbow_link.STL"/>
      </geometry>
      <material name="">
        <color rgba="0.898039215686275 0.917647058823529 0.929411764705882 1"/>
      </material>
    </visual>
    <collision>
      <origin rpy="0 1.5707963267948966 0" xyz="0.1 0 0.065"/>
      <geometry>
        <cylinder length="0.09" radius="0.025"/>
      </geometry>
    </collision>
  </link>
  <joint name="joint3" type="revolute">
    <origin rpy="0 0 0" xyz="-0.3 0 0"/>
    <parent link="upper_arm_link"/>
    <child link="elbow_link"/>
    <axis xyz="0 -1 0"/>
    <limit effort="15.0" lower="0" upper="4.188" velocity="20.0"/>
  </joint>
  <link name="lower_arm_link">
    <inertial>
      <origin rpy="0 0 0" xyz="0.259131075077944 0.000561908541381621 1.63162643829207E-06"/>
      <mass value="0.237992640601958"/>
      <inertia ixx="8.1971938649496E-05" ixy="-1.16251515064919E-05" ixz="2.28325579601934E-17" iyy="0.00109175485406717" iyz="1.11323021885341E-10" izz="0.00106324137537677"/>
    </inertial>
    <visual>
      <origin rpy="0 0 0" xyz="0 0 0"/>
      <geometry>
        <mesh filename="package://lion_armed_description/meshes/lower_arm_link.STL"/>
      </geometry>
      <material name="">
        <color rgba="0.686274509803922 0.658823529411765 0.63921568627451 1"/>
      </material>
    </visual>
    <collision>
      <origin rpy="0 0 0" xyz="0.27 0 0"/>
      <geometry>
        <box size="0.24 0.025 0.05"/>
      </geometry>
    </collision>
  </link>
  <joint name="joint4" type="revolute">
    <origin rpy="0 0 0" xyz="0 -4.7023E-05 0.064998"/>
    <parent link="elbow_link"/>
    <child link="lower_arm_link"/>
    <axis xyz="-1 0 0"/>
    <limit effort="15.0" lower="-3.14" upper="3.14" velocity="20.0"/>
  </joint>
  <link name="wrist_link">
    <inertial>
      <origin rpy="0 0 0" xyz="0.048236 0.0079922 -2.4907E-05"/>
      <mass value="0.20482"/>
      <inertia ixx="0.00010001" ixy="2.0576E-05" ixz="3.8277E-08" iyy="0.00015052" iyz="-7.2338E-08" izz="0.00017601"/>
    </inertial>
    <visual>
      <origin rpy="0 0 0" xyz="0 0 0"/>
      <geometry>
        <mesh filename="package://lion_armed_description/meshes/wrist_link.STL"/>
      </geometry>
      <material name="">
        <color rgba="0.68627 0.65882 0.63922 1"/>
      </material>
    </visual>
    <collision>
      <origin rpy="0 1.5707963267948966 0" xyz="0.06 0 0"/>
      <geometry>
        <cylinder length="0.035" radius="0.025"/>
      </geometry>
    </collision>
  </link>
  <joint name="joint5" type="revolute">
    <origin rpy="0 0 0" xyz="0.354 4.7023E-05 0"/>
    <parent link="lower_arm_link"/>
    <child link="wrist_link"/>
    <axis xyz="0 -1 0"/>
    <limit effort="15.0" lower="-1.571" upper="1.571" velocity="20.0"/>
  </joint>
  <link name="hand_link">
    <inertial>
      <origin rpy="0 0 0" xyz="0.12082 -0.00020649 0.0038737"/>
      <mass value="0.34303"/>
      <inertia ixx="0.0001455" ixy="-1.5454E-06" ixz="2.0576E-05" iyy="0.00041843" iyz="3.6627E-07" izz="0.00037382"/>
    </inertial>
    <visual>
      <origin rpy="0 0 0" xyz="0 0 0"/>
      <geometry>
        <mesh filename="package://lion_armed_description/meshes/hand_link.STL"/>
      </geometry>
      <material name="">
        <color rgba="0.89804 0.91765 0.92941 1"/>
      </material>
    </visual>
    <collision>
      <origin rpy="0 0 0" xyz="0.135 0.01 0"/>
      <geometry>
        <box size="0.1 0.06 0.05"/>
      </geometry>
    </collision>
  </link>
  <joint name="joint6" type="revolute">
    <origin rpy="0 0 0" xyz="0 0 0"/>
    <parent link="wrist_link"/>
    <child link="hand_link"/>
    <axis xyz="1 0 0"/>
    <limit effort="15.0" lower="-3.14" upper="3.14" velocity="20.0"/>
  </joint>
  <!-- Imu is fixed to the base link -->
  <joint name="unitree_imu_joint" type="fixed">
    <origin rpy="0. 0. 0." xyz="0. 0. 0."/>
    <parent link="base"/>
    <child link="unitree_imu"/>
  </joint>
  <!-- Imu link -->
  <link name="unitree_imu">
    <inertial>
      <mass value="0.01"/>
      <origin rpy="0 0 0" xyz="0 0 0"/>
      <inertia ixx="0.000001" ixy="0" ixz="0" iyy="0.000001" iyz="0" izz="0.000001"/>
    </inertial>
    <visual>
      <origin rpy="0 0 0" xyz="0 0 0"/>
      <geometry>
        <box size="0.015 0.015 0.004"/>
      </geometry>
    </visual>
    <material name="orange">
      <color rgba="255 108 10 255"/>
    </material>
  </link>

</robot>
