<?xml version="1.0" ?>
<!-- =================================================================================== -->
<!-- |    This document was autogenerated by xacro from lion.xacro                     | -->
<!-- |    EDITING THIS FILE BY HAND IS NOT RECOMMENDED                                 | -->
<!-- =================================================================================== -->
<robot name="lion">
  <!--Quadruped Model *******************************************************************************************-->
  <link name="base_link">
    <inertial>
      <origin rpy="0 0 0" xyz="-0.000638750070817345 -0.00672058356158241 -0.00556735378698432"/>
      <mass value="8.286"/>
      <inertia ixx="0.056529" ixy="-0.001107" ixz="-3.045E-05" iyy="0.14156" iyz="-0.0011531" izz="0.17939"/>
      </inertial>
    <visual>
      <origin rpy="0 0 0" xyz="0 0 0"/>
      <geometry>
        <mesh filename="package://lion_armed/meshes/base_link.STL"/>
      </geometry>
      <material name="">
        <color rgba="0.792156862745098 0.819607843137255 0.933333333333333 1"/>
      </material>
    </visual>
    <collision>
      <origin rpy="0 0 0" xyz="0 0 0"/>
      <geometry>
        <mesh filename="package://lion_armed/meshes/base_link.STL"/>
      </geometry>
    </collision>
  </link>
  <link name="LegFR_hip">
    <inertial>
      <origin rpy="0 0 0" xyz="-0.0050797 -0.047183 4.172E-05"/>
      <mass value="1.095"/>
      <inertia ixx="0.0010035" ixy="-0.00021789" ixz="1.433E-06" iyy="0.0014762" iyz="1.005E-06" izz="0.0012507"/>
    </inertial>
    <visual>
      <origin rpy="0 0 0" xyz="0 0 0"/>
      <geometry>
        <mesh filename="package://lion_armed/meshes/hip_Link.STL"/>
      </geometry>
      <material name="">
        <color rgba="0.79216 0.81961 0.93333 1"/>
      </material>
    </visual>
    <collision>
      <origin rpy="0 0 0" xyz="0 0 0"/>
      <geometry>
        <mesh filename="package://lion_armed/meshes/hip_Link.STL"/>
      </geometry>
    </collision>
  </link>
  <joint name="JointFR_abad" type="revolute">
    <origin rpy="0.0 0.0 0 " xyz="0.2467 -0.09 0"/>
    <parent link="base_link"/>
    <child link="LegFR_hip"/>
    <axis xyz="1 0 0"/>
    <limit effort="55" lower="-3.0" upper="3.0" velocity="30"/>
  </joint>
  <link name="LegFR_thigh">
    <inertial>''
      <origin rpy="0 0 0" xyz="-2.7705E-05 -0.089684 -0.23198"/>
      <mass value="1.556"/>
      <inertia ixx="0.015631" ixy="-8.61E-07" ixz="-6.078E-06" iyy="0.016183" iyz="0.0004689" izz="0.0011163"/>
    </inertial>
    <visual>
      <origin rpy="0 0 0" xyz="0 0 0"/>
      <geometry>
        <mesh filename="package://lion_armed/meshes/thigh_Link.STL"/>
      </geometry>
      <material name="">
        <color rgba="0.79216 0.81961 0.93333 1"/>
      </material>
    </visual>
    <collision>
      <origin rpy="0 0 0" xyz="0 0 0"/>
      <geometry>
        <mesh filename="package://lion_armed/meshes/thigh_Link.STL"/>
      </geometry>
    </collision>
  </link>
  <joint name="JointFR_hip" type="revolute">
    <origin rpy="0 0.0 0" xyz="0 0 0"/>
    <parent link="LegFR_hip"/>
    <child link="LegFR_thigh"/>
    <axis xyz="0 -1 0"/>
    <limit effort="55" lower="-3.0" upper="3.0" velocity="30"/>
  </joint>
  <link name="LegFR_shank">
    <inertial>
      <origin rpy="0 0 0" xyz="2.05E-06 -0.12517 -0.080832"/>
      <mass value="0.233"/>
      <inertia ixx="0.0033053" ixy="-3.64E-07" ixz="4.028E-06" iyy="0.0033126" iyz="-0.00013194" izz="4.3236E-05"/>
    </inertial>
    <visual>
      <origin rpy="0 0 0" xyz="0 0 0"/>
      <geometry>
        <mesh filename="package://lion_armed/meshes/shank_Link.STL"/>
      </geometry>
      <material name="">
        <color rgba="0.79216 0.81961 0.93333 1"/>
      </material>
    </visual>
    <collision>
      <origin rpy="0 0 0" xyz="0 0 0"/>
      <geometry>
        <mesh filename="package://lion_armed/meshes/shank_Link.STL"/>
      </geometry>
    </collision>
  </link>
  <joint name="JointFR_knee" type="revolute">
    <origin rpy="0 0 0" xyz="0 0 -0.3"/>
    <parent link="LegFR_thigh"/>
    <child link="LegFR_shank"/>
    <axis xyz="0 -1 0"/>
    <limit effort="55" lower="-3.0" upper="3.0" velocity="30"/>
  </joint>
  <link name="LegFR_foot">
  <contact>
      <friction_anchor/>
      <stiffness value="30000.0"/>
      <damping value="1000.0"/>
      <spinning_friction value="0.3"/>
      <lateral_friction value="3.0"/>
    </contact>
    <inertial>
      <origin rpy="0 0 0" xyz="0.0002617 0.00017365 0.0085579"/>
      <!-- <mass value="0.03946"/> -->
      <mass value="0.01"/>
      <!-- <inertia ixx="1.4527E-05" ixy="-8.5021E-08" ixz="-4.0103E-07" iyy="1.4601E-05" iyz="-2.6548E-07" izz="6.2338E-06"/> -->
      <inertia ixx="0.001983" ixy="0.000245" ixz="0.000013" 
                iyy="0.002103" iyz="0.0000015" izz="0.000408"/>
    </inertial>
    <visual>
      <origin rpy="0 0 0" xyz="0 0 0"/>
      <geometry>
        <mesh filename="package://lion_armed/meshes/foot_Link.STL"/>
      </geometry>
      <material name="">
        <color rgba="0.79216 0.81961 0.93333 1"/>
      </material>
    </visual>
    <collision>
      <origin rpy="0 0 0" xyz="0 0 0"/>
      <geometry>
        <mesh filename="package://lion_armed/meshes/foot_Link.STL"/>
      </geometry>
    </collision>
  </link>
  <joint name="JointFR_foot" type="fixed">
    <origin rpy="0 0 0" xyz="0 -0.119 -0.3105"/>
    <parent link="LegFR_shank"/>
    <child link="LegFR_foot"/>
    <axis xyz="0 0 1"/>

  </joint>
  <link name="LegFL_hip">
    <inertial>
      <origin rpy="0 0 0" xyz="-0.0050797 -0.047183 4.172E-05"/>
      <!-- <mass value="0.39498"/> -->
      <mass value="1.095"/>
      <inertia ixx="0.0010035" ixy="-0.00021789" ixz="1.433E-06" iyy="0.0014762" iyz="1.005E-06" izz="0.0012507"/>
    </inertial>
    <visual>
      <origin rpy="0 0 0" xyz="0 0 0"/>
      <geometry>
        <mesh filename="package://lion_armed/meshes/hip_Link.STL"/>
      </geometry>
      <material name="">
        <color rgba="0.79216 0.81961 0.93333 1"/>
      </material>
    </visual>
    <collision>
      <origin rpy="0 0 0" xyz="0 0 0"/>
      <geometry>
        <mesh filename="package://lion_armed/meshes/hip_Link.STL"/>
      </geometry>
    </collision>
  </link>
  <joint name="JointFL_abad" type="revolute">
    <origin rpy="3.141592653589793 0.0 0 " xyz="0.2467 0.09 0"/>
    <parent link="base_link"/>
    <child link="LegFL_hip"/>
    <axis xyz="1 0 0"/>
    <limit effort="55" lower="-3.0" upper="3.0" velocity="30"/>
  </joint>
  <link name="LegFL_thigh">
    <inertial>
      <origin rpy="0 0 0" xyz="-2.7705E-05 -0.089684 -0.23198"/>
      <mass value="1.556"/>
      <inertia ixx="0.015631" ixy="-8.61E-07" ixz="-6.078E-06" iyy="0.016183" iyz="0.0004689" izz="0.0011163"/>
    </inertial>
    <visual>
      <origin rpy="0 0 0" xyz="0 0 0"/>
      <geometry>
        <mesh filename="package://lion_armed/meshes/thigh_Link.STL"/>
      </geometry>
      <material name="">
        <color rgba="0.79216 0.81961 0.93333 1"/>
      </material>
    </visual>
    <collision>
      <origin rpy="0 0 0" xyz="0 0 0"/>
      <geometry>
        <mesh filename="package://lion_armed/meshes/thigh_Link.STL"/>
      </geometry>
    </collision>
  </link>
  <joint name="JointFL_hip" type="revolute">
    <origin rpy="0 3.141592653589793 0" xyz="0 0 0"/>
    <parent link="LegFL_hip"/>
    <child link="LegFL_thigh"/>
    <axis xyz="0 1 0"/>
    <limit effort="55" lower="-3.0" upper="3.0" velocity="30"/>
  </joint>
  <link name="LegFL_shank">
    <inertial>
      <origin rpy="0 0 0" xyz="2.05E-06 -0.12517 -0.080832"/>
      <mass value="0.233"/>
      <inertia ixx="0.0033053" ixy="-3.64E-07" ixz="4.028E-06" iyy="0.0033126" iyz="-0.00013194" izz="4.3236E-05"/>
    </inertial>
    <visual>
      <origin rpy="0 0 0" xyz="0 0 0"/>
      <geometry>
        <mesh filename="package://lion_armed/meshes/shank_Link.STL"/>
      </geometry>
      <material name="">
        <color rgba="0.79216 0.81961 0.93333 1"/>
      </material>
    </visual>
    <collision>
      <origin rpy="0 0 0" xyz="0 0 0"/>
      <geometry>
        <mesh filename="package://lion_armed/meshes/shank_Link.STL"/>
      </geometry>
    </collision>
  </link>
  <joint name="JointFL_knee" type="revolute">
    <origin rpy="0 0 0" xyz="0 0 -0.3"/>
    <parent link="LegFL_thigh"/>
    <child link="LegFL_shank"/>
    <axis xyz="0 1 0"/>
    <limit effort="55" lower="-3.0" upper="3.0" velocity="30"/>
  </joint>
  <link name="LegFL_foot">
  <contact>
      <friction_anchor/>
      <stiffness value="30000.0"/>
      <damping value="1000.0"/>
      <spinning_friction value="0.3"/>
      <lateral_friction value="3.0"/>
    </contact>
    <inertial>
      <origin rpy="0 0 0" xyz="0.0002617 0.00017365 0.0085579"/>
      <!-- <mass value="0.03946"/> -->
      <mass value="0.01"/>
      <!-- <inertia ixx="1.4527E-05" ixy="-8.5021E-08" ixz="-4.0103E-07" iyy="1.4601E-05" iyz="-2.6548E-07" izz="6.2338E-06"/> -->
      <inertia ixx="0.001983" ixy="0.000245" ixz="0.000013" 
                iyy="0.002103" iyz="0.0000015" izz="0.000408"/>
    </inertial>
    <visual>
      <origin rpy="0 0 0" xyz="0 0 0"/>
      <geometry>
        <mesh filename="package://lion_armed/meshes/foot_Link.STL"/>
      </geometry>
      <material name="">
        <color rgba="0.79216 0.81961 0.93333 1"/>
      </material>
    </visual>
    <collision>
      <origin rpy="0 0 0" xyz="0 0 0"/>
      <geometry>
        <mesh filename="package://lion_armed/meshes/foot_Link.STL"/>
      </geometry>
    </collision>
  </link>
  <joint name="JointFL_foot" type="fixed">
    <origin rpy="0 0 0" xyz="0 -0.119 -0.3105"/>
    <parent link="LegFL_shank"/>
    <child link="LegFL_foot"/>
    <axis xyz="0 0 1"/>

  </joint>
  <link name="LegHR_hip">
    <inertial>
      <origin rpy="0 0 0" xyz="-0.0050797 -0.047183 4.172E-05"/>
      <mass value="1.095"/>
      <inertia ixx="0.0010035" ixy="-0.00021789" ixz="1.433E-06" iyy="0.0014762" iyz="1.005E-06" izz="0.0012507"/>
    </inertial>
    <visual>
      <origin rpy="0 0 0" xyz="0 0 0"/>
      <geometry>
        <mesh filename="package://lion_armed/meshes/hip_Link.STL"/>
      </geometry>
      <material name="">
        <color rgba="0.79216 0.81961 0.93333 1"/>
      </material>
    </visual>
    <collision>
      <origin rpy="0 0 0" xyz="0 0 0"/>
      <geometry>
        <mesh filename="package://lion_armed/meshes/hip_Link.STL"/>
      </geometry>
    </collision>
  </link>
  <joint name="JointHR_abad" type="revolute">
    <origin rpy="0.0 3.141592653589793 0 " xyz="-0.2467 -0.09 0"/>
    <parent link="base_link"/>
    <child link="LegHR_hip"/>
    <axis xyz="-1 0 0"/>
    <limit effort="55" lower="-3.0" upper="3.0" velocity="30"/>
  </joint>
  <link name="LegHR_thigh">
    <inertial>
      <origin rpy="0 0 0" xyz="-2.7705E-05 -0.089684 -0.23198"/>
      <mass value="1.556"/>
      <inertia ixx="0.015631" ixy="-8.61E-07" ixz="-6.078E-06" iyy="0.016183" iyz="0.0004689" izz="0.0011163"/>
    </inertial>
    <visual>
      <origin rpy="0 0 0" xyz="0 0 0"/>
      <geometry>
        <mesh filename="package://lion_armed/meshes/thigh_Link.STL"/>
      </geometry>
      <material name="">
        <color rgba="0.79216 0.81961 0.93333 1"/>
      </material>
    </visual>
    <collision>
      <origin rpy="0 0 0" xyz="0 0 0"/>
      <geometry>
        <mesh filename="package://lion_armed/meshes/thigh_Link.STL"/>
      </geometry>
    </collision>
  </link>
  <joint name="JointHR_hip" type="revolute">
    <origin rpy="0 3.141592653589793 0" xyz="0 0 0"/>
    <parent link="LegHR_hip"/>
    <child link="LegHR_thigh"/>
    <axis xyz="0 -1 0"/>
    <limit effort="55" lower="-3.0" upper="3.0" velocity="30"/>
  </joint>
  <link name="LegHR_shank">
    <inertial>
      <origin rpy="0 0 0" xyz="2.05E-06 -0.12517 -0.080832"/>
      <mass value="0.233"/>
      <inertia ixx="0.0033053" ixy="-3.64E-07" ixz="4.028E-06" iyy="0.0033126" iyz="-0.00013194" izz="4.3236E-05"/>
    </inertial>
    <visual>
      <origin rpy="0 0 0" xyz="0 0 0"/>
      <geometry>
        <mesh filename="package://lion_armed/meshes/shank_Link.STL"/>
      </geometry>
      <material name="">
        <color rgba="0.79216 0.81961 0.93333 1"/>
      </material>
    </visual>
    <collision>
      <origin rpy="0 0 0" xyz="0 0 0"/>
      <geometry>
        <mesh filename="package://lion_armed/meshes/shank_Link.STL"/>
      </geometry>
    </collision>
  </link>
  <joint name="JointHR_knee" type="revolute">
    <origin rpy="0 0 0" xyz="0 0 -0.3"/>
    <parent link="LegHR_thigh"/>
    <child link="LegHR_shank"/>
    <axis xyz="0 -1 0"/>
    <limit effort="55" lower="-3.0" upper="3.0" velocity="30"/>
  </joint>
  <link name="LegHR_foot">
<contact>
      <friction_anchor/>
      <stiffness value="30000.0"/>
      <damping value="1000.0"/>
      <spinning_friction value="0.3"/>
      <lateral_friction value="3.0"/>
    </contact>
    <inertial>
      <origin rpy="0 0 0" xyz="0.0002617 0.00017365 0.0085579"/>
      <!-- <mass value="0.03946"/> -->
      <mass value="0.01"/>
      <!-- <inertia ixx="1.4527E-05" ixy="-8.5021E-08" ixz="-4.0103E-07" iyy="1.4601E-05" iyz="-2.6548E-07" izz="6.2338E-06"/> -->
      <inertia ixx="0.001983" ixy="0.000245" ixz="0.000013" 
                iyy="0.002103" iyz="0.0000015" izz="0.000408"/>
    </inertial>
    <visual>
      <origin rpy="0 0 0" xyz="0 0 0"/>
      <geometry>
        <mesh filename="package://lion_armed/meshes/foot_Link.STL"/>
      </geometry>
      <material name="">
        <color rgba="0.79216 0.81961 0.93333 1"/>
      </material>
    </visual>
    <collision>
      <origin rpy="0 0 0" xyz="0 0 0"/>
      <geometry>
        <mesh filename="package://lion_armed/meshes/foot_Link.STL"/>
      </geometry>
    </collision>
  </link>
  <joint name="JointHR_foot" type="fixed">
    <origin rpy="0 0 0" xyz="0 -0.119 -0.3105"/>
    <parent link="LegHR_shank"/>
    <child link="LegHR_foot"/>
    <axis xyz="0 0 1"/>

  </joint>
  <link name="LegHL_hip">
    <inertial>
      <origin rpy="0 0 0" xyz="-0.0050797 -0.047183 4.172E-05"/>
      <mass value="1.095"/>
      <inertia ixx="0.0010035" ixy="-0.00021789" ixz="1.433E-06" iyy="0.0014762" iyz="1.005E-06" izz="0.0012507"/>
    </inertial>
    <visual>
      <origin rpy="0 0 0" xyz="0 0 0"/>
      <geometry>
        <mesh filename="package://lion_armed/meshes/hip_Link.STL"/>
      </geometry>
      <material name="">
        <color rgba="0.79216 0.81961 0.93333 1"/>
      </material>
    </visual>
    <collision>
      <origin rpy="0 0 0" xyz="0 0 0"/>
      <geometry>
        <mesh filename="package://lion_armed/meshes/hip_Link.STL"/>
      </geometry>
    </collision>
  </link>
  <joint name="JointHL_abad" type="revolute">
    <origin rpy="3.141592653589793 3.141592653589793 0 " xyz="-0.2467 0.09 0"/>
    <parent link="base_link"/>
    <child link="LegHL_hip"/>
    <axis xyz="-1 0 0"/>
    <limit effort="55" lower="-3.0" upper="3.0" velocity="30"/>
  </joint>
  <link name="LegHL_thigh">
    <inertial>
      <origin rpy="0 0 0" xyz="-2.7705E-05 -0.089684 -0.23198"/>
      <mass value="1.556"/>
      <inertia ixx="0.015631" ixy="-8.61E-07" ixz="-6.078E-06" iyy="0.016183" iyz="0.0004689" izz="0.0011163"/>
    </inertial>
    <visual>
      <origin rpy="0 0 0" xyz="0 0 0"/>
      <geometry>
        <mesh filename="package://lion_armed/meshes/thigh_Link.STL"/>
      </geometry>
      <material name="">
        <color rgba="0.79216 0.81961 0.93333 1"/>
      </material>
    </visual>
    <collision>
      <origin rpy="0 0 0" xyz="0 0 0"/>
      <geometry>
        <mesh filename="package://lion_armed/meshes/thigh_Link.STL"/>
      </geometry>
    </collision>
  </link>
  <joint name="JointHL_hip" type="revolute">
    <origin rpy="0 6.283185307179586 0" xyz="0 0 0"/>
    <parent link="LegHL_hip"/>
    <child link="LegHL_thigh"/>
    <axis xyz="0 1 0"/>
    <limit effort="55" lower="-3.0" upper="3.0" velocity="30"/>
  </joint>
  <link name="LegHL_shank">
    <inertial>
      <origin rpy="0 0 0" xyz="2.05E-06 -0.12517 -0.080832"/>
      <mass value="0.233"/>
      <inertia ixx="0.0033053" ixy="-3.64E-07" ixz="4.028E-06" iyy="0.0033126" iyz="-0.00013194" izz="4.3236E-05"/>
    </inertial>
    <visual>
      <origin rpy="0 0 0" xyz="0 0 0"/>
      <geometry>
        <mesh filename="package://lion_armed/meshes/shank_Link.STL"/>
      </geometry>
      <material name="">
        <color rgba="0.79216 0.81961 0.93333 1"/>
      </material>
    </visual>
    <collision>
      <origin rpy="0 0 0" xyz="0 0 0"/>
      <geometry>
        <mesh filename="package://lion_armed/meshes/shank_Link.STL"/>
      </geometry>
    </collision>
  </link>
  <joint name="JointHL_knee" type="revolute">
    <origin rpy="0 0 0" xyz="0 0 -0.3"/>
    <parent link="LegHL_thigh"/>
    <child link="LegHL_shank"/>
    <axis xyz="0 1 0"/>
    <limit effort="55" lower="-3.0" upper="3.0" velocity="30"/>
  </joint>
  <link name="LegHL_foot">
  <contact>
      <friction_anchor/>
      <stiffness value="30000.0"/>
      <damping value="1000.0"/>
      <spinning_friction value="0.3"/>
      <lateral_friction value="3.0"/>
    </contact>
    <inertial>
      <origin rpy="0 0 0" xyz="0.0002617 0.00017365 0.0085579"/>
      <!-- <mass value="0.03946"/> -->
      <mass value="0.01"/>
      <!-- <inertia ixx="1.4527E-05" ixy="-8.5021E-08" ixz="-4.0103E-07" iyy="1.4601E-05" iyz="-2.6548E-07" izz="6.2338E-06"/> -->
      <inertia ixx="0.001983" ixy="0.000245" ixz="0.000013" 
                iyy="0.002103" iyz="0.0000015" izz="0.000408"/>
    </inertial>
    <visual>
      <origin rpy="0 0 0" xyz="0 0 0"/>
      <geometry>
        <mesh filename="package://lion_armed/meshes/foot_Link.STL"/>
      </geometry>
      <material name="">
        <color rgba="0.79216 0.81961 0.93333 1"/>
      </material>
    </visual>
    <collision>
      <origin rpy="0 0 0" xyz="0 0 0"/>
      <geometry>
        <mesh filename="package://lion_armed/meshes/foot_Link.STL"/>
      </geometry>
    </collision>
  </link>
  <joint name="JointHL_foot" type="fixed">
    <origin rpy="0 0 0" xyz="0 -0.119 -0.3105"/>
    <parent link="LegHL_shank"/>
    <child link="LegHL_foot"/>
    <axis xyz="0 0 1"/>
  </joint>
  <!-- Arm Model ********************************************************************************************************  -->
  <link
    name="arm_base_link">
    <inertial>
      <origin
        xyz="-2.655E-05 -0.00013067 0.042361"
        rpy="0 0 0" />
      <mass
        value="0.91201" />
      <inertia
        ixx="0.00076553"
        ixy="3.0928E-06"
        ixz="4.0773E-06"
        iyy="0.000762"
        iyz="-3.7031E-06"
        izz="0.00081713" />
    </inertial>
    <visual>
      <origin
        xyz="0 0 0"
        rpy="0 0 0" />
      <geometry>
        <mesh
          filename="package://lion_armed/meshes/arm_base_link.STL" />
      </geometry>
      <material
        name="">
        <color
          rgba="0.89804 0.91765 0.92941 1" />
      </material>
    </visual>
    <collision>
      <origin
        xyz="0 0 0"
        rpy="0 0 0" />
      <geometry>
        <mesh
          filename="package://lion_armed/meshes/arm_base_link.STL" />
      </geometry>
    </collision>
  </link>
  <joint
    name="body_arm"
    type="fixed">
    <origin
      xyz="0.1075 0 0.0635"
      rpy="0 0 0" />
    <parent
      link="base_link" />
    <child
      link="arm_base_link" />
    <axis
      xyz="0 0 -1" />
    <limit
      lower="0"
      upper="0"
      effort="0"
      velocity="0" />
  </joint>
  <link
    name="shoulder_link">
    <inertial>
      <origin
        xyz="4.6648E-05 0.00012015 -0.0013725"
        rpy="0 0 0" />
      <mass
        value="1.8076" />
      <inertia
        ixx="0.0070637"
        ixy="-1.1248E-07"
        ixz="4.2676E-06"
        iyy="0.0014085"
        iyz="-1.6705E-06"
        izz="0.0069672" />
    </inertial>
    <visual>
      <origin
        xyz="0 0 0"
        rpy="0 0 0" />
      <geometry>
        <mesh
          filename="package://lion_armed/meshes/shoulder_link.STL" />
      </geometry>
      <material
        name="">
        <color
          rgba="0.89804 0.91765 0.92941 1" />
      </material>
    </visual>
    <collision>
      <origin
        xyz="0 0 0"
        rpy="0 0 0" />
      <geometry>
        <mesh
          filename="package://lion_armed/meshes/shoulder_link.STL" />
      </geometry>
    </collision>
  </link>
  <joint
    name="joint1"
    type="continuous">
    <origin
      xyz="0 0 0.128"
      rpy="0 0 0" />
    <parent
      link="arm_base_link" />
    <child
      link="shoulder_link" />
    <axis
      xyz="0 0 -1" />
    <limit
      lower="0"
      upper="0"
      effort="0"
      velocity="0" />
  </joint>
  <link
    name="upper_arm_link">
    <inertial>
      <origin
        xyz="-0.16223 -0.00053457 -9.6145E-14"
        rpy="0 0 0" />
      <mass
        value="0.20654" />
      <inertia
        ixx="0.00017354"
        ixy="4.7067E-05"
        ixz="-8.9112E-16"
        iyy="0.0023721"
        iyz="4.6757E-16"
        izz="0.0023909" />
    </inertial>
    <visual>
      <origin
        xyz="0 0 0"
        rpy="0 0 0" />
      <geometry>
        <mesh
          filename="package://lion_armed/meshes/upper_arm_link.STL" />
      </geometry>
      <material
        name="">
        <color
          rgba="1 1 1 1" />
      </material>
    </visual>
    <collision>
      <origin
        xyz="0 0 0"
        rpy="0 0 0" />
      <geometry>
        <mesh
          filename="package://lion_armed/meshes/upper_arm_link.STL" />
      </geometry>
    </collision>
  </link>
  <joint
    name="joint2"
    type="continuous">
    <origin
      xyz="0 0 0"
      rpy="0 0 0" />
    <parent
      link="shoulder_link" />
    <child
      link="upper_arm_link" />
    <axis
      xyz="0 1 0" />
    <limit
      lower="0"
      upper="0"
      effort="0"
      velocity="0" />
  </joint>
  <link
    name="elbow_link">
    <inertial>
      <origin
        xyz="0.0776630957799923 -5.66684882904192E-06 0.0506455368238795"
        rpy="0 0 0" />
      <mass
        value="0.19779615464477" />
      <inertia
        ixx="0.000172309779571075"
        ixy="5.40217940566371E-08"
        ixz="-0.000202557640418278"
        iyy="0.000759104610858122"
        iyz="2.15341009549695E-08"
        izz="0.000636430285987363" />
    </inertial>
    <visual>
      <origin
        xyz="0 0 0"
        rpy="0 0 0" />
      <geometry>
        <mesh
          filename="package://lion_armed/meshes/elbow_link.STL" />
      </geometry>
      <material
        name="">
        <color
          rgba="0.898039215686275 0.917647058823529 0.929411764705882 1" />
      </material>
    </visual>
    <collision>
      <origin
        xyz="0 0 0"
        rpy="0 0 0" />
      <geometry>
        <mesh
          filename="package://lion_armed/meshes/elbow_link.STL" />
      </geometry>
    </collision>
  </link>
  <joint
    name="joint3"
    type="continuous">
    <origin
      xyz="-0.3 0 0"
      rpy="0 0 0" />
    <parent
      link="upper_arm_link" />
    <child
      link="elbow_link" />
    <axis
      xyz="0 -1 0" />
    <limit
      lower="0"
      upper="0"
      effort="0"
      velocity="0" />
  </joint>
  <link
    name="lower_arm_link">
    <inertial>
      <origin
        xyz="0.259131075077944 0.000561908541381621 1.63162643829207E-06"
        rpy="0 0 0" />
      <mass
        value="0.237992640601958" />
      <inertia
        ixx="8.1971938649496E-05"
        ixy="-1.16251515064919E-05"
        ixz="2.28325579601934E-17"
        iyy="0.00109175485406717"
        iyz="1.11323021885341E-10"
        izz="0.00106324137537677" />
    </inertial>
    <visual>
      <origin
        xyz="0 0 0"
        rpy="0 0 0" />
      <geometry>
        <mesh
          filename="package://lion_armed/meshes/lower_arm_link.STL" />
      </geometry>
      <material
        name="">
        <color
          rgba="0.686274509803922 0.658823529411765 0.63921568627451 1" />
      </material>
    </visual>
    <collision>
      <origin
        xyz="0 0 0"
        rpy="0 0 0" />
      <geometry>
        <mesh
          filename="package://lion_armed/meshes/lower_arm_link.STL" />
      </geometry>
    </collision>
  </link>
  <joint
    name="joint4"
    type="continuous">
    <origin
      xyz="0 -4.7023E-05 0.064998"
      rpy="0 0 0" />
    <parent
      link="elbow_link" />
    <child
      link="lower_arm_link" />
    <axis
      xyz="-1 0 0" />
    <limit
      lower="0"
      upper="0"
      effort="0"
      velocity="0" />
  </joint>
  <link
    name="wrist_link">
    <inertial>
      <origin
        xyz="0.048236 0.0079922 -2.4907E-05"
        rpy="0 0 0" />
      <mass
        value="0.20482" />
      <inertia
        ixx="0.00010001"
        ixy="2.0576E-05"
        ixz="3.8277E-08"
        iyy="0.00015052"
        iyz="-7.2338E-08"
        izz="0.00017601" />
    </inertial>
    <visual>
      <origin
        xyz="0 0 0"
        rpy="0 0 0" />
      <geometry>
        <mesh
          filename="package://lion_armed/meshes/wrist_link.STL" />
      </geometry>
      <material
        name="">
        <color
          rgba="0.68627 0.65882 0.63922 1" />
      </material>
    </visual>
    <collision>
      <origin
        xyz="0 0 0"
        rpy="0 0 0" />
      <geometry>
        <mesh
          filename="package://lion_armed/meshes/wrist_link.STL" />
      </geometry>
    </collision>
  </link>
  <joint
    name="joint5"
    type="continuous">
    <origin
      xyz="0.354 4.7023E-05 0"
      rpy="0 0 0" />
    <parent
      link="lower_arm_link" />
    <child
      link="wrist_link" />
    <axis
      xyz="0 -1 0" />
    <limit
      lower="0"
      upper="0"
      effort="0"
      velocity="0" />
  </joint>
  <link
    name="hand_link">
    <inertial>
      <origin
        xyz="0.12082 -0.00020649 0.0038737"
        rpy="0 0 0" />
      <mass
        value="0.34303" />
      <inertia
        ixx="0.0001455"
        ixy="-1.5454E-06"
        ixz="2.0576E-05"
        iyy="0.00041843"
        iyz="3.6627E-07"
        izz="0.00037382" />
    </inertial>
    <visual>
      <origin
        xyz="0 0 0"
        rpy="0 0 0" />
      <geometry>
        <mesh
          filename="package://lion_armed/meshes/hand_link.STL" />
      </geometry>
      <material
        name="">
        <color
          rgba="0.89804 0.91765 0.92941 1" />
      </material>
    </visual>
    <collision>
      <origin
        xyz="0 0 0"
        rpy="0 0 0" />
      <geometry>
        <mesh
          filename="package://lion_armed/meshes/hand_link.STL" />
      </geometry>
    </collision>
  </link>
  <joint
    name="joint6"
    type="continuous">
    <origin
      xyz="0 0 0"
      rpy="0 0 0" />
    <parent
      link="wrist_link" />
    <child
      link="hand_link" />
    <axis
      xyz="1 0 0" />
    <limit
      lower="0"
      upper="0"
      effort="0"
      velocity="0" />
  </joint>
</robot>

