<?xml version="1.0" ?>
<!-- =================================================================================== -->
<!-- |    This document was autogenerated by xacro from robot.xacro                    | -->
<!-- |    EDITING THIS FILE BY HAND IS NOT RECOMMENDED                                 | -->
<!-- =================================================================================== -->
<robot name="lion">
  <!-- <xacro:arg name="robot_type" default="lion"/> -->
  <!-- ros_control plugin -->
  <gazebo>
    <plugin filename="liblegged_hw_sim.so" name="gazebo_ros_control">
      <robotNamespace>/</robotNamespace>
      <robotParam>legged_robot_description</robotParam>
      <robotSimType>legged_gazebo/QuadHWSim</robotSimType>
      <!-- <controlPeriod>0.002</controlPeriod> -->
    </plugin>
  </gazebo>
  <gazebo>
    <plugin filename="libgazebo_ros_p3d.so" name="p3d_base_controller">
      <alwaysOn>true</alwaysOn>
      <updateRate>1000.0</updateRate>
      <bodyName>base</bodyName>
      <topicName>ground_truth/state</topicName>
      <gaussianNoise>0</gaussianNoise>
      <frameName>world</frameName>
      <xyzOffsets>0 0 0</xyzOffsets>
      <rpyOffsets>0 0 0</rpyOffsets>
    </plugin>
  </gazebo>
  <gazebo reference="base">
    <maxVel>100.</maxVel>
    <kp>10000.</kp>
    <kd>0.</kd>
  </gazebo>
  <gazebo reference="stick_link">
    <mu1>0.2</mu1>
    <mu2>0.2</mu2>
    <material>Gazebo/White</material>
  </gazebo>
  <!-- LF leg -->
  <gazebo reference="LF_hip">
    <mu1>0.2</mu1>
    <mu2>0.2</mu2>
    <material>Gazebo/DarkGrey</material>
  </gazebo>
  <gazebo reference="LF_thigh">
    <mu1>0.2</mu1>
    <mu2>0.2</mu2>
    <self_collide>1</self_collide>
    <material>Gazebo/DarkGrey</material>
    <kp value="1000000.0"/>
    <kd value="1.0"/>
  </gazebo>
  <gazebo reference="LF_calf">
    <mu1>0.2</mu1>
    <mu2>0.2</mu2>
    <self_collide>1</self_collide>
  </gazebo>
  <gazebo reference="LF_FOOT">
    <mu1>0.6</mu1>
    <mu2>0.6</mu2>
    <self_collide>1</self_collide>
    <material>Gazebo/DarkGrey</material>
    <kp value="1000000.0"/>
    <kd value="100.0"/>
  </gazebo>
  <!-- RF leg -->
  <gazebo reference="RF_hip">
    <mu1>0.2</mu1>
    <mu2>0.2</mu2>
    <material>Gazebo/DarkGrey</material>
  </gazebo>
  <gazebo reference="RF_thigh">
    <mu1>0.2</mu1>
    <mu2>0.2</mu2>
    <self_collide>1</self_collide>
    <material>Gazebo/DarkGrey</material>
    <kp value="1000000.0"/>
    <kd value="1.0"/>
  </gazebo>
  <gazebo reference="RF_calf">
    <mu1>0.2</mu1>
    <mu2>0.2</mu2>
    <self_collide>1</self_collide>
  </gazebo>
  <gazebo reference="RF_FOOT">
    <mu1>0.6</mu1>
    <mu2>0.6</mu2>
    <self_collide>1</self_collide>
    <material>Gazebo/DarkGrey</material>
    <kp value="1000000.0"/>
    <kd value="1.0"/>
  </gazebo>
  <!-- LH leg -->
  <gazebo reference="LH_hip">
    <mu1>0.2</mu1>
    <mu2>0.2</mu2>
    <material>Gazebo/DarkGrey</material>
  </gazebo>
  <gazebo reference="LH_thigh">
    <mu1>0.2</mu1>
    <mu2>0.2</mu2>
    <self_collide>1</self_collide>
    <material>Gazebo/DarkGrey</material>
    <kp value="1000000.0"/>
    <kd value="1.0"/>
  </gazebo>
  <gazebo reference="LH_calf">
    <mu1>0.2</mu1>
    <mu2>0.2</mu2>
    <self_collide>1</self_collide>
  </gazebo>
  <gazebo reference="LH_FOOT">
    <mu1>0.6</mu1>
    <mu2>0.6</mu2>
    <self_collide>1</self_collide>
    <material>Gazebo/DarkGrey</material>
    <kp value="1000000.0"/>
    <kd value="1.0"/>
  </gazebo>
  <!-- RH leg -->
  <gazebo reference="RH_hip">
    <mu1>0.2</mu1>
    <mu2>0.2</mu2>
    <material>Gazebo/DarkGrey</material>
  </gazebo>
  <gazebo reference="RH_thigh">
    <mu1>0.2</mu1>
    <mu2>0.2</mu2>
    <self_collide>1</self_collide>
    <material>Gazebo/DarkGrey</material>
    <kp value="1000000.0"/>
    <kd value="1.0"/>
  </gazebo>
  <gazebo reference="RH_calf">
    <mu1>0.2</mu1>
    <mu2>0.2</mu2>
    <self_collide>1</self_collide>
  </gazebo>
  <gazebo reference="RH_FOOT">
    <mu1>0.6</mu1>
    <mu2>0.6</mu2>
    <self_collide>1</self_collide>
    <material>Gazebo/DarkGrey</material>
    <kp value="1000000.0"/>
    <kd value="1.0"/>
  </gazebo>
  <!-- <xacro:include filename="$(find lion_description)/urdf/$(arg robot_type)/const.xacro"/> -->
  <!--Robot Model*******************************************************************************************-->
  <link name="base">
    <inertial>
      <origin rpy="0 0 0" xyz="-0.000638750070817345 -0.00672058356158241 -0.00556735378698432"/>
      <mass value="8.286"/>
      <inertia ixx="0.056529" ixy="-0.001107" ixz="-3.045E-05" iyy="0.14156" iyz="-0.0011531" izz="0.17939"/>
    </inertial>
    <visual>
      <origin rpy="0 0 0" xyz="0 0 0"/>
      <geometry>
        <mesh filename="package://lion_description/meshes/base_link.STL"/>
      </geometry>
      <material name="">
        <color rgba="0.792156862745098 0.819607843137255 0.933333333333333 1"/>
      </material>
    </visual>
    <collision>
      <origin rpy="0 0 0" xyz="0 0 0"/>
      <geometry>
        <box size="0.35 0.24 0.14"/>
      </geometry>
    </collision>
  </link>
  <link name="RF_hip">
    <inertial>
      <origin rpy="0 0 0" xyz="-0.0050797 -0.047183 4.172E-05"/>
      <mass value="1.095"/>
      <inertia ixx="0.0010035" ixy="-0.00021789" ixz="1.433E-06" iyy="0.0014762" iyz="1.005E-06" izz="0.0012507"/>
    </inertial>
    <visual>
      <origin rpy="0 0 0" xyz="0 0 0"/>
      <geometry>
        <mesh filename="package://lion_description/meshes/hip_Link.STL"/>
      </geometry>
      <material name="">
        <color rgba="0.79216 0.81961 0.93333 1"/>
      </material>
    </visual>
    <collision>
      <origin rpy="1.5707963267948966 0 0" xyz="0.0 -0.05 0"/>
      <geometry>
        <!-- <box size="0.05 0.03 0.3"/> -->
        <cylinder length="0.06" radius="0.05"/>
      </geometry>
    </collision>
  </link>
  <joint name="RF_HAA" type="revolute">
    <origin rpy="0.0 0.0 0 " xyz="0.2467 -0.09 0"/>
    <parent link="base"/>
    <child link="RF_hip"/>
    <axis xyz="1 0 0"/>
    <limit effort="55" lower="-1.0" upper="1.0" velocity="30"/>
  </joint>
  <link name="RF_thigh">
    <inertial>
      ''
            
      <origin rpy="0 0 0" xyz="-2.7705E-05 -0.089684 -0.23198"/>
      <mass value="1.556"/>
      <inertia ixx="0.015631" ixy="-8.61E-07" ixz="-6.078E-06" iyy="0.016183" iyz="0.0004689" izz="0.0011163"/>
    </inertial>
    <visual>
      <origin rpy="0 0 0" xyz="0 0 0"/>
      <geometry>
        <mesh filename="package://lion_description/meshes/thigh_Link.STL"/>
      </geometry>
      <material name="">
        <color rgba="0.79216 0.81961 0.93333 1"/>
      </material>
    </visual>
    <collision>
      <origin rpy="1.5707963267948966 0 0" xyz="0 -0.09 -0.3"/>
      <geometry>
        <!-- <box size="0.05 0.03 0.3"/> -->
        <cylinder length="0.06" radius="0.05"/>
      </geometry>
    </collision>
  </link>
  <joint name="RF_HFE" type="revolute">
    <origin rpy="0 0.0 0" xyz="0 0 0"/>
    <parent link="RF_hip"/>
    <child link="RF_thigh"/>
    <axis xyz="0 1 0"/>
    <limit effort="55" lower="-3.0" upper="3.0" velocity="30"/>
  </joint>
  <link name="RF_calf">
    <inertial>
      <origin rpy="0 0 0" xyz="2.05E-06 -0.12517 -0.080832"/>
      <mass value="0.233"/>
      <inertia ixx="0.0033053" ixy="-3.64E-07" ixz="4.028E-06" iyy="0.0033126" iyz="-0.00013194" izz="4.3236E-05"/>
    </inertial>
    <visual>
      <origin rpy="0 0 0" xyz="0 0 0"/>
      <geometry>
        <mesh filename="package://lion_description/meshes/shank_Link.STL"/>
      </geometry>
      <material name="">
        <color rgba="0.79216 0.81961 0.93333 1"/>
      </material>
    </visual>
    <collision>
      <origin rpy="0 0 0" xyz="0 -0.119 -0.15"/>
      <geometry>
        <cylinder length="0.2" radius="0.01"/>
      </geometry>
    </collision>
  </link>
  <joint name="RF_KFE" type="revolute">
    <origin rpy="0 0 0" xyz="0 0 -0.3"/>
    <parent link="RF_thigh"/>
    <child link="RF_calf"/>
    <axis xyz="0 1 0"/>
    <limit effort="55" lower="-3.0" upper="-0.5" velocity="30"/>
  </joint>
  <link name="RF_FOOT">
    <contact>
      <friction_anchor/>
      <stiffness value="30000.0"/>
      <damping value="1000.0"/>
      <spinning_friction value="0.3"/>
      <lateral_friction value="3.0"/>
    </contact>
    <inertial>
      <origin rpy="0 0 0" xyz="0.0002617 0.00017365 0.0085579"/>
      <!-- <mass value="0.03946"/> -->
      <mass value="0.01"/>
      <!-- <inertia ixx="1.4527E-05" ixy="-8.5021E-08" ixz="-4.0103E-07" iyy="1.4601E-05" iyz="-2.6548E-07" izz="6.2338E-06"/> -->
      <inertia ixx="0.001983" ixy="0.000245" ixz="0.000013" iyy="0.002103" iyz="0.0000015" izz="0.000408"/>
    </inertial>
    <visual>
      <origin rpy="0 0 0" xyz="0 0 0"/>
      <geometry>
        <mesh filename="package://lion_description/meshes/foot_Link.STL"/>
      </geometry>
      <material name="">
        <color rgba="0.79216 0.81961 0.93333 1"/>
      </material>
    </visual>
    <collision>
      <origin rpy="0 0 0" xyz="0 0 0"/>
      <geometry>
        <sphere radius="0.02"/>
      </geometry>
    </collision>
  </link>
  <joint name="JointFR_foot" type="fixed">
    <origin rpy="0 0 0" xyz="0 -0.119 -0.3105"/>
    <parent link="RF_calf"/>
    <child link="RF_FOOT"/>
    <axis xyz="0 0 1"/>
  </joint>
  <link name="LF_hip">
    <inertial>
      <origin rpy="0 0 0" xyz="-0.0050797 -0.047183 4.172E-05"/>
      <!-- <mass value="0.39498"/> -->
      <mass value="1.095"/>
      <inertia ixx="0.0010035" ixy="-0.00021789" ixz="1.433E-06" iyy="0.0014762" iyz="1.005E-06" izz="0.0012507"/>
    </inertial>
    <visual>
      <origin rpy="0 0 0" xyz="0 0 0"/>
      <geometry>
        <mesh filename="package://lion_description/meshes/hip_Link.STL"/>
      </geometry>
      <material name="">
        <color rgba="0.79216 0.81961 0.93333 1"/>
      </material>
    </visual>
    <collision>
      <origin rpy="1.5707963267948966 0 0" xyz="0.0 -0.05 0"/>
      <geometry>
        <!-- <box size="0.05 0.03 0.3"/> -->
        <cylinder length="0.06" radius="0.05"/>
      </geometry>
    </collision>
  </link>
  <joint name="LF_HAA" type="revolute">
    <origin rpy="3.141592653589793 0.0 0 " xyz="0.2467 0.09 0"/>
    <parent link="base"/>
    <child link="LF_hip"/>
    <axis xyz="1 0 0"/>
    <limit effort="55" lower="-1.0" upper="1.0" velocity="30"/>
  </joint>
  <link name="LF_thigh">
    <inertial>
      <origin rpy="0 0 0" xyz="-2.7705E-05 -0.089684 -0.23198"/>
      <mass value="1.556"/>
      <inertia ixx="0.015631" ixy="-8.61E-07" ixz="-6.078E-06" iyy="0.016183" iyz="0.0004689" izz="0.0011163"/>
    </inertial>
    <visual>
      <origin rpy="0 0 0" xyz="0 0 0"/>
      <geometry>
        <mesh filename="package://lion_description/meshes/thigh_Link.STL"/>
      </geometry>
      <material name="">
        <color rgba="0.79216 0.81961 0.93333 1"/>
      </material>
    </visual>
    <collision>
      <origin rpy="1.5707963267948966 0 0" xyz="0 -0.09 -0.3"/>
      <geometry>
        <!-- <box size="0.05 0.03 0.3"/> -->
        <cylinder length="0.06" radius="0.05"/>
      </geometry>
    </collision>
  </link>
  <joint name="LF_HFE" type="revolute">
    <origin rpy="0 3.141592653589793 0" xyz="0 0 0"/>
    <parent link="LF_hip"/>
    <child link="LF_thigh"/>
    <axis xyz="0 -1 0"/>
    <limit effort="55" lower="-3.0" upper="3.0" velocity="30"/>
  </joint>
  <link name="LF_calf">
    <inertial>
      <origin rpy="0 0 0" xyz="2.05E-06 -0.12517 -0.080832"/>
      <mass value="0.233"/>
      <inertia ixx="0.0033053" ixy="-3.64E-07" ixz="4.028E-06" iyy="0.0033126" iyz="-0.00013194" izz="4.3236E-05"/>
    </inertial>
    <visual>
      <origin rpy="0 0 0" xyz="0 0 0"/>
      <geometry>
        <mesh filename="package://lion_description/meshes/shank_Link.STL"/>
      </geometry>
      <material name="">
        <color rgba="0.79216 0.81961 0.93333 1"/>
      </material>
    </visual>
    <collision>
      <origin rpy="0 0 0" xyz="0 -0.119 -0.15"/>
      <geometry>
        <cylinder length="0.2" radius="0.01"/>
      </geometry>
    </collision>
  </link>
  <joint name="LF_KFE" type="revolute">
    <origin rpy="0 0 0" xyz="0 0 -0.3"/>
    <parent link="LF_thigh"/>
    <child link="LF_calf"/>
    <axis xyz="0 -1 0"/>
    <limit effort="55" lower="-3.0" upper="-0.5" velocity="30"/>
  </joint>
  <link name="LF_FOOT">
    <contact>
      <friction_anchor/>
      <stiffness value="30000.0"/>
      <damping value="1000.0"/>
      <spinning_friction value="0.3"/>
      <lateral_friction value="3.0"/>
    </contact>
    <inertial>
      <origin rpy="0 0 0" xyz="0.0002617 0.00017365 0.0085579"/>
      <!-- <mass value="0.03946"/> -->
      <mass value="0.01"/>
      <!-- <inertia ixx="1.4527E-05" ixy="-8.5021E-08" ixz="-4.0103E-07" iyy="1.4601E-05" iyz="-2.6548E-07" izz="6.2338E-06"/> -->
      <inertia ixx="0.001983" ixy="0.000245" ixz="0.000013" iyy="0.002103" iyz="0.0000015" izz="0.000408"/>
    </inertial>
    <visual>
      <origin rpy="0 0 0" xyz="0 0 0"/>
      <geometry>
        <mesh filename="package://lion_description/meshes/foot_Link.STL"/>
      </geometry>
      <material name="">
        <color rgba="0.79216 0.81961 0.93333 1"/>
      </material>
    </visual>
    <collision>
      <origin rpy="0 0 0" xyz="0 0 0"/>
      <geometry>
        <sphere radius="0.02"/>
      </geometry>
    </collision>
  </link>
  <joint name="JointFL_foot" type="fixed">
    <origin rpy="0 0 0" xyz="0 -0.119 -0.3105"/>
    <parent link="LF_calf"/>
    <child link="LF_FOOT"/>
    <axis xyz="0 0 1"/>
  </joint>
  <link name="RH_hip">
    <inertial>
      <origin rpy="0 0 0" xyz="-0.0050797 -0.047183 4.172E-05"/>
      <mass value="1.095"/>
      <inertia ixx="0.0010035" ixy="-0.00021789" ixz="1.433E-06" iyy="0.0014762" iyz="1.005E-06" izz="0.0012507"/>
    </inertial>
    <visual>
      <origin rpy="0 0 0" xyz="0 0 0"/>
      <geometry>
        <mesh filename="package://lion_description/meshes/hip_Link.STL"/>
      </geometry>
      <material name="">
        <color rgba="0.79216 0.81961 0.93333 1"/>
      </material>
    </visual>
    <collision>
      <origin rpy="1.5707963267948966 0 0" xyz="0.0 -0.05 0"/>
      <geometry>
        <!-- <box size="0.05 0.03 0.3"/> -->
        <cylinder length="0.06" radius="0.05"/>
      </geometry>
    </collision>
  </link>
  <joint name="RH_HAA" type="revolute">
    <origin rpy="0.0 3.141592653589793 0 " xyz="-0.2467 -0.09 0"/>
    <parent link="base"/>
    <child link="RH_hip"/>
    <axis xyz="-1 0 0"/>
    <limit effort="55" lower="-1.0" upper="1.0" velocity="30"/>
  </joint>
  <link name="RH_thigh">
    <inertial>
      <origin rpy="0 0 0" xyz="-2.7705E-05 -0.089684 -0.23198"/>
      <mass value="1.556"/>
      <inertia ixx="0.015631" ixy="-8.61E-07" ixz="-6.078E-06" iyy="0.016183" iyz="0.0004689" izz="0.0011163"/>
    </inertial>
    <visual>
      <origin rpy="0 0 0" xyz="0 0 0"/>
      <geometry>
        <mesh filename="package://lion_description/meshes/thigh_Link.STL"/>
      </geometry>
      <material name="">
        <color rgba="0.79216 0.81961 0.93333 1"/>
      </material>
    </visual>
    <collision>
      <origin rpy="1.5707963267948966 0 0" xyz="0 -0.09 -0.3"/>
      <geometry>
        <!-- <box size="0.05 0.03 0.3"/> -->
        <cylinder length="0.06" radius="0.05"/>
      </geometry>
    </collision>
  </link>
  <joint name="RH_HFE" type="revolute">
    <origin rpy="0 3.141592653589793 0" xyz="0 0 0"/>
    <parent link="RH_hip"/>
    <child link="RH_thigh"/>
    <axis xyz="0 1 0"/>
    <limit effort="55" lower="-3.0" upper="3.0" velocity="30"/>
  </joint>
  <link name="RH_calf">
    <inertial>
      <origin rpy="0 0 0" xyz="2.05E-06 -0.12517 -0.080832"/>
      <mass value="0.233"/>
      <inertia ixx="0.0033053" ixy="-3.64E-07" ixz="4.028E-06" iyy="0.0033126" iyz="-0.00013194" izz="4.3236E-05"/>
    </inertial>
    <visual>
      <origin rpy="0 0 0" xyz="0 0 0"/>
      <geometry>
        <mesh filename="package://lion_description/meshes/shank_Link.STL"/>
      </geometry>
      <material name="">
        <color rgba="0.79216 0.81961 0.93333 1"/>
      </material>
    </visual>
    <collision>
      <origin rpy="0 0 0" xyz="0 -0.119 -0.15"/>
      <geometry>
        <cylinder length="0.2" radius="0.01"/>
      </geometry>
    </collision>
  </link>
  <joint name="RH_KFE" type="revolute">
    <origin rpy="0 0 0" xyz="0 0 -0.3"/>
    <parent link="RH_thigh"/>
    <child link="RH_calf"/>
    <axis xyz="0 1 0"/>
    <limit effort="55" lower="-3.0" upper="-0.5" velocity="30"/>
  </joint>
  <link name="RH_FOOT">
    <contact>
      <friction_anchor/>
      <stiffness value="30000.0"/>
      <damping value="1000.0"/>
      <spinning_friction value="0.3"/>
      <lateral_friction value="3.0"/>
    </contact>
    <inertial>
      <origin rpy="0 0 0" xyz="0.0002617 0.00017365 0.0085579"/>
      <!-- <mass value="0.03946"/> -->
      <mass value="0.01"/>
      <!-- <inertia ixx="1.4527E-05" ixy="-8.5021E-08" ixz="-4.0103E-07" iyy="1.4601E-05" iyz="-2.6548E-07" izz="6.2338E-06"/> -->
      <inertia ixx="0.001983" ixy="0.000245" ixz="0.000013" iyy="0.002103" iyz="0.0000015" izz="0.000408"/>
    </inertial>
    <visual>
      <origin rpy="0 0 0" xyz="0 0 0"/>
      <geometry>
        <mesh filename="package://lion_description/meshes/foot_Link.STL"/>
      </geometry>
      <material name="">
        <color rgba="0.79216 0.81961 0.93333 1"/>
      </material>
    </visual>
    <collision>
      <origin rpy="0 0 0" xyz="0 0 0"/>
      <geometry>
        <sphere radius="0.02"/>
      </geometry>
    </collision>
  </link>
  <joint name="JointHR_foot" type="fixed">
    <origin rpy="0 0 0" xyz="0 -0.119 -0.3105"/>
    <parent link="RH_calf"/>
    <child link="RH_FOOT"/>
    <axis xyz="0 0 1"/>
  </joint>
  <link name="LH_hip">
    <inertial>
      <origin rpy="0 0 0" xyz="-0.0050797 -0.047183 4.172E-05"/>
      <mass value="1.095"/>
      <inertia ixx="0.0010035" ixy="-0.00021789" ixz="1.433E-06" iyy="0.0014762" iyz="1.005E-06" izz="0.0012507"/>
    </inertial>
    <visual>
      <origin rpy="0 0 0" xyz="0 0 0"/>
      <geometry>
        <mesh filename="package://lion_description/meshes/hip_Link.STL"/>
      </geometry>
      <material name="">
        <color rgba="0.79216 0.81961 0.93333 1"/>
      </material>
    </visual>
    <collision>
      <origin rpy="1.5707963267948966 0 0" xyz="0.0 -0.05 0"/>
      <geometry>
        <!-- <box size="0.05 0.03 0.3"/> -->
        <cylinder length="0.06" radius="0.05"/>
      </geometry>
    </collision>
  </link>
  <joint name="LH_HAA" type="revolute">
    <origin rpy="3.141592653589793 3.141592653589793 0 " xyz="-0.2467 0.09 0"/>
    <parent link="base"/>
    <child link="LH_hip"/>
    <axis xyz="-1 0 0"/>
    <limit effort="55" lower="-1.0" upper="1.0" velocity="30"/>
  </joint>
  <link name="LH_thigh">
    <inertial>
      <origin rpy="0 0 0" xyz="-2.7705E-05 -0.089684 -0.23198"/>
      <mass value="1.556"/>
      <inertia ixx="0.015631" ixy="-8.61E-07" ixz="-6.078E-06" iyy="0.016183" iyz="0.0004689" izz="0.0011163"/>
    </inertial>
    <visual>
      <origin rpy="0 0 0" xyz="0 0 0"/>
      <geometry>
        <mesh filename="package://lion_description/meshes/thigh_Link.STL"/>
      </geometry>
      <material name="">
        <color rgba="0.79216 0.81961 0.93333 1"/>
      </material>
    </visual>
    <collision>
      <origin rpy="1.5707963267948966 0 0" xyz="0 -0.09 -0.3"/>
      <geometry>
        <!-- <box size="0.05 0.03 0.3"/> -->
        <cylinder length="0.06" radius="0.05"/>
      </geometry>
    </collision>
  </link>
  <joint name="LH_HFE" type="revolute">
    <origin rpy="0 6.283185307179586 0" xyz="0 0 0"/>
    <parent link="LH_hip"/>
    <child link="LH_thigh"/>
    <axis xyz="0 -1 0"/>
    <limit effort="55" lower="-3.0" upper="3.0" velocity="30"/>
  </joint>
  <link name="LH_calf">
    <inertial>
      <origin rpy="0 0 0" xyz="2.05E-06 -0.12517 -0.080832"/>
      <mass value="0.233"/>
      <inertia ixx="0.0033053" ixy="-3.64E-07" ixz="4.028E-06" iyy="0.0033126" iyz="-0.00013194" izz="4.3236E-05"/>
    </inertial>
    <visual>
      <origin rpy="0 0 0" xyz="0 0 0"/>
      <geometry>
        <mesh filename="package://lion_description/meshes/shank_Link.STL"/>
      </geometry>
      <material name="">
        <color rgba="0.79216 0.81961 0.93333 1"/>
      </material>
    </visual>
    <collision>
      <origin rpy="0 0 0" xyz="0 -0.119 -0.15"/>
      <geometry>
        <cylinder length="0.2" radius="0.01"/>
      </geometry>
    </collision>
  </link>
  <joint name="LH_KFE" type="revolute">
    <origin rpy="0 0 0" xyz="0 0 -0.3"/>
    <parent link="LH_thigh"/>
    <child link="LH_calf"/>
    <axis xyz="0 -1 0"/>
    <limit effort="55" lower="-3.0" upper="-0.5" velocity="30"/>
  </joint>
  <link name="LH_FOOT">
    <contact>
      <friction_anchor/>
      <stiffness value="30000.0"/>
      <damping value="1000.0"/>
      <spinning_friction value="0.3"/>
      <lateral_friction value="3.0"/>
    </contact>
    <inertial>
      <origin rpy="0 0 0" xyz="0.0002617 0.00017365 0.0085579"/>
      <!-- <mass value="0.03946"/> -->
      <mass value="0.01"/>
      <!-- <inertia ixx="1.4527E-05" ixy="-8.5021E-08" ixz="-4.0103E-07" iyy="1.4601E-05" iyz="-2.6548E-07" izz="6.2338E-06"/> -->
      <inertia ixx="0.001983" ixy="0.000245" ixz="0.000013" iyy="0.002103" iyz="0.0000015" izz="0.000408"/>
    </inertial>
    <visual>
      <origin rpy="0 0 0" xyz="0 0 0"/>
      <geometry>
        <mesh filename="package://lion_description/meshes/foot_Link.STL"/>
      </geometry>
      <material name="">
        <color rgba="0.79216 0.81961 0.93333 1"/>
      </material>
    </visual>
    <collision>
      <origin rpy="0 0 0" xyz="0 0 0"/>
      <geometry>
        <sphere radius="0.02"/>
      </geometry>
    </collision>
  </link>
  <joint name="JointHL_foot" type="fixed">
    <origin rpy="0 0 0" xyz="0 -0.119 -0.3105"/>
    <parent link="LH_calf"/>
    <child link="LH_FOOT"/>
    <axis xyz="0 0 1"/>
  </joint>
  <!-- Imu is fixed to the base link -->
  <joint name="unitree_imu_joint" type="fixed">
    <origin rpy="0. 0. 0." xyz="0. 0. 0."/>
    <parent link="base"/>
    <child link="unitree_imu"/>
  </joint>
  <!-- Imu link -->
  <link name="unitree_imu">
    <inertial>
      <mass value="0.01"/>
      <origin rpy="0 0 0" xyz="0 0 0"/>
      <inertia ixx="0.000001" ixy="0" ixz="0" iyy="0.000001" iyz="0" izz="0.000001"/>
    </inertial>
    <visual>
      <origin rpy="0 0 0" xyz="0 0 0"/>
      <geometry>
        <box size="0.015 0.015 0.004"/>
      </geometry>
    </visual>
    <material name="orange">
      <color rgba="255 108 10 255"/>
    </material>
  </link>
  <gazebo reference="unitree_imu">
    <material>Gazebo/Orange</material>
  </gazebo>
  <gazebo reference="unitree_imu_joint">
    <disableFixedJointLumping>true</disableFixedJointLumping>
  </gazebo>
  <transmission name="RF_HAA_tran">
    <type>transmission_interface/SimpleTransmission</type>
    <joint name="RF_HAA">
      <hardwareInterface>hardware_interface/EffortJointInterface</hardwareInterface>
    </joint>
    <actuator name="RF_HAA_motor">
      <hardwareInterface>hardware_interface/EffortJointInterface</hardwareInterface>
      <mechanicalReduction>1</mechanicalReduction>
    </actuator>
  </transmission>
  <transmission name="RF_HFE_tran">
    <type>transmission_interface/SimpleTransmission</type>
    <joint name="RF_HFE">
      <hardwareInterface>hardware_interface/EffortJointInterface</hardwareInterface>
    </joint>
    <actuator name="RF_HFE_motor">
      <hardwareInterface>hardware_interface/EffortJointInterface</hardwareInterface>
      <mechanicalReduction>1</mechanicalReduction>
    </actuator>
  </transmission>
  <transmission name="RF_KFE_tran">
    <type>transmission_interface/SimpleTransmission</type>
    <joint name="RF_KFE">
      <hardwareInterface>hardware_interface/EffortJointInterface</hardwareInterface>
    </joint>
    <actuator name="RF_KFE_motor">
      <hardwareInterface>hardware_interface/EffortJointInterface</hardwareInterface>
      <mechanicalReduction>1</mechanicalReduction>
    </actuator>
  </transmission>
  <transmission name="LF_HAA_tran">
    <type>transmission_interface/SimpleTransmission</type>
    <joint name="LF_HAA">
      <hardwareInterface>hardware_interface/EffortJointInterface</hardwareInterface>
    </joint>
    <actuator name="LF_HAA_motor">
      <hardwareInterface>hardware_interface/EffortJointInterface</hardwareInterface>
      <mechanicalReduction>1</mechanicalReduction>
    </actuator>
  </transmission>
  <transmission name="LF_HFE_tran">
    <type>transmission_interface/SimpleTransmission</type>
    <joint name="LF_HFE">
      <hardwareInterface>hardware_interface/EffortJointInterface</hardwareInterface>
    </joint>
    <actuator name="LF_HFE_motor">
      <hardwareInterface>hardware_interface/EffortJointInterface</hardwareInterface>
      <mechanicalReduction>1</mechanicalReduction>
    </actuator>
  </transmission>
  <transmission name="LF_KFE_tran">
    <type>transmission_interface/SimpleTransmission</type>
    <joint name="LF_KFE">
      <hardwareInterface>hardware_interface/EffortJointInterface</hardwareInterface>
    </joint>
    <actuator name="LF_KFE_motor">
      <hardwareInterface>hardware_interface/EffortJointInterface</hardwareInterface>
      <mechanicalReduction>1</mechanicalReduction>
    </actuator>
  </transmission>
  <transmission name="RH_HAA_tran">
    <type>transmission_interface/SimpleTransmission</type>
    <joint name="RH_HAA">
      <hardwareInterface>hardware_interface/EffortJointInterface</hardwareInterface>
    </joint>
    <actuator name="RH_HAA_motor">
      <hardwareInterface>hardware_interface/EffortJointInterface</hardwareInterface>
      <mechanicalReduction>1</mechanicalReduction>
    </actuator>
  </transmission>
  <transmission name="RH_HFE_tran">
    <type>transmission_interface/SimpleTransmission</type>
    <joint name="RH_HFE">
      <hardwareInterface>hardware_interface/EffortJointInterface</hardwareInterface>
    </joint>
    <actuator name="RH_HFE_motor">
      <hardwareInterface>hardware_interface/EffortJointInterface</hardwareInterface>
      <mechanicalReduction>1</mechanicalReduction>
    </actuator>
  </transmission>
  <transmission name="RH_KFE_tran">
    <type>transmission_interface/SimpleTransmission</type>
    <joint name="RH_KFE">
      <hardwareInterface>hardware_interface/EffortJointInterface</hardwareInterface>
    </joint>
    <actuator name="RH_KFE_motor">
      <hardwareInterface>hardware_interface/EffortJointInterface</hardwareInterface>
      <mechanicalReduction>1</mechanicalReduction>
    </actuator>
  </transmission>
  <transmission name="LH_HAA_tran">
    <type>transmission_interface/SimpleTransmission</type>
    <joint name="LH_HAA">
      <hardwareInterface>hardware_interface/EffortJointInterface</hardwareInterface>
    </joint>
    <actuator name="LH_HAA_motor">
      <hardwareInterface>hardware_interface/EffortJointInterface</hardwareInterface>
      <mechanicalReduction>1</mechanicalReduction>
    </actuator>
  </transmission>
  <transmission name="LH_HFE_tran">
    <type>transmission_interface/SimpleTransmission</type>
    <joint name="LH_HFE">
      <hardwareInterface>hardware_interface/EffortJointInterface</hardwareInterface>
    </joint>
    <actuator name="LH_HFE_motor">
      <hardwareInterface>hardware_interface/EffortJointInterface</hardwareInterface>
      <mechanicalReduction>1</mechanicalReduction>
    </actuator>
  </transmission>
  <transmission name="LH_KFE_tran">
    <type>transmission_interface/SimpleTransmission</type>
    <joint name="LH_KFE">
      <hardwareInterface>hardware_interface/EffortJointInterface</hardwareInterface>
    </joint>
    <actuator name="LH_KFE_motor">
      <hardwareInterface>hardware_interface/EffortJointInterface</hardwareInterface>
      <mechanicalReduction>1</mechanicalReduction>
    </actuator>
  </transmission>
</robot>
