<?xml version="1.0"?>

<robot xmlns:xacro="http://www.ros.org/wiki/xacro" name="lion">

  <!-- <xacro:arg name="robot_type" default="lion"/> -->

  <!-- <xacro:include filename="$(find lion_arx3_description)/lion.urdf"/> -->
  <xacro:include filename="$(find lion_arx3_description)/common/transmission.xacro" />
  <xacro:include filename="$(find lion_arx3_description)/common/gazebo.xacro" />
  <xacro:include filename="$(find lion_arx3_description)/common/imu.xacro" />

  <!-- <xacro:include filename="$(find lion_arx3_description)/urdf/$(arg robot_type)/const.xacro"/> -->


  <!--Quadruped
  Model*******************************************************************************************-->
  <link name="base">
    <inertial>
      <origin rpy="0 0 0" xyz="-0.000638750070817345 -0.00672058356158241 -0.00556735378698432" />
      <mass value="8.286" />
      <inertia ixx="0.056529" ixy="-0.001107" ixz="-3.045E-05" iyy="0.14156" iyz="-0.0011531"
        izz="0.17939" />
    </inertial>
    <visual>
      <origin rpy="0 0 0" xyz="0 0 0" />
      <geometry>
        <mesh filename="package://lion_arx3_description/meshes/base_link.STL" />
      </geometry>
      <material name="">
        <color rgba="0.792156862745098 0.819607843137255 0.933333333333333 1" />
      </material>
    </visual>
    <collision>
      <origin rpy="0 0 0" xyz="0 0 0" />
      <geometry>
        <box size="0.35 0.24 0.14" />
      </geometry>
    </collision>
  </link>
  <link name="RF_hip">
    <inertial>
      <origin rpy="0 0 0" xyz="-0.0050797 -0.047183 4.172E-05" />
      <mass value="1.095" />
      <inertia ixx="0.0010035" ixy="-0.00021789" ixz="1.433E-06" iyy="0.0014762" iyz="1.005E-06"
        izz="0.0012507" />
    </inertial>
    <visual>
      <origin rpy="0 0 0" xyz="0 0 0" />
      <geometry>
        <mesh filename="package://lion_arx3_description/meshes/hip_Link.STL" />
      </geometry>
      <material name="">
        <color rgba="0.79216 0.81961 0.93333 1" />
      </material>
    </visual>
    <collision>
      <origin rpy="${pi/2.0} 0 0" xyz="0.0 -0.05 0" />
      <geometry>
        <!-- <box size="0.05 0.03 0.3"/> -->
        <cylinder length="0.06" radius="0.05" />
      </geometry>
    </collision>
  </link>
  <joint name="RF_HAA" type="revolute">
    <origin rpy="0.0 0.0 0 " xyz="0.2467 -0.09 0" />
    <parent link="base" />
    <child link="RF_hip" />
    <axis xyz="1 0 0" />
    <limit effort="55" lower="-1.0" upper="1.0" velocity="30" />
  </joint>
  <link name="RF_thigh">
    <inertial>'' <origin rpy="0 0 0" xyz="-2.7705E-05 -0.089684 -0.23198" />
        <mass value="1.556" />
        <inertia
        ixx="0.015631" ixy="-8.61E-07" ixz="-6.078E-06" iyy="0.016183" iyz="0.0004689"
        izz="0.0011163" />
    </inertial>
    <visual>
      <origin rpy="0 0 0" xyz="0 0 0" />
      <geometry>
        <mesh filename="package://lion_arx3_description/meshes/thigh_Link.STL" />
      </geometry>
      <material name="">
        <color rgba="0.79216 0.81961 0.93333 1" />
      </material>
    </visual>
    <collision>
      <origin rpy="${pi/2.0} 0 0" xyz="0 -0.09 -0.3" />
      <geometry>
        <!-- <box size="0.05 0.03 0.3"/> -->
        <cylinder length="0.06" radius="0.05" />
      </geometry>
    </collision>
  </link>
  <joint name="RF_HFE" type="revolute">
    <origin rpy="0 0.0 0" xyz="0 0 0" />
    <parent link="RF_hip" />
    <child link="RF_thigh" />
    <axis xyz="0 1 0" />
    <limit effort="55" lower="-3.0" upper="3.0" velocity="30" />
  </joint>
  <link name="RF_calf">
    <inertial>
      <origin rpy="0 0 0" xyz="2.05E-06 -0.12517 -0.080832" />
      <mass value="0.233" />
      <inertia ixx="0.0033053" ixy="-3.64E-07" ixz="4.028E-06" iyy="0.0033126" iyz="-0.00013194"
        izz="4.3236E-05" />
    </inertial>
    <visual>
      <origin rpy="0 0 0" xyz="0 0 0" />
      <geometry>
        <mesh filename="package://lion_arx3_description/meshes/shank_Link.STL" />
      </geometry>
      <material name="">
        <color rgba="0.79216 0.81961 0.93333 1" />
      </material>
    </visual>
    <collision>
      <origin rpy="0 0 0" xyz="0 -0.119 -0.15" />
      <geometry>
        <cylinder length="0.2" radius="0.01" />
      </geometry>
    </collision>
  </link>
  <joint name="RF_KFE" type="revolute">
    <origin rpy="0 0 0" xyz="0 0 -0.3" />
    <parent link="RF_thigh" />
    <child link="RF_calf" />
    <axis xyz="0 1 0" />
    <limit effort="55" lower="-3.0" upper="-0.5" velocity="30" />
  </joint>
  <link name="RF_FOOT">
    <contact>
      <friction_anchor />
      <stiffness value="30000.0" />
      <damping value="1000.0" />
      <spinning_friction value="0.3" />
      <lateral_friction value="3.0" />
    </contact>
    <inertial>
      <origin rpy="0 0 0" xyz="0.0002617 0.00017365 0.0085579" />
      <!-- <mass value="0.03946"/> -->
      <mass value="0.01" />
      <!-- <inertia ixx="1.4527E-05" ixy="-8.5021E-08" ixz="-4.0103E-07" iyy="1.4601E-05"
      iyz="-2.6548E-07" izz="6.2338E-06"/> -->
      <inertia ixx="0.001983" ixy="0.000245" ixz="0.000013"
        iyy="0.002103" iyz="0.0000015" izz="0.000408" />
    </inertial>
    <visual>
      <origin rpy="0 0 0" xyz="0 0 0" />
      <geometry>
        <mesh filename="package://lion_arx3_description/meshes/foot_Link.STL" />
      </geometry>
      <material name="">
        <color rgba="0.79216 0.81961 0.93333 1" />
      </material>
    </visual>
    <collision>
      <origin rpy="0 0 0" xyz="0 0 0.002" />
      <geometry>
        <sphere radius="0.02" />
      </geometry>
    </collision>
  </link>
  <joint name="JointFR_foot" type="fixed">
    <origin rpy="0 0 0" xyz="0 -0.119 -0.3105" />
    <parent link="RF_calf" />
    <child link="RF_FOOT" />
    <axis xyz="0 0 1" />

  </joint>
  <link name="LF_hip">
    <inertial>
      <origin rpy="0 0 0" xyz="-0.0050797 -0.047183 4.172E-05" />
      <!-- <mass value="0.39498"/> -->
      <mass value="1.095" />
      <inertia ixx="0.0010035" ixy="-0.00021789" ixz="1.433E-06" iyy="0.0014762" iyz="1.005E-06"
        izz="0.0012507" />
    </inertial>
    <visual>
      <origin rpy="0 0 0" xyz="0 0 0" />
      <geometry>
        <mesh filename="package://lion_arx3_description/meshes/hip_Link.STL" />
      </geometry>
      <material name="">
        <color rgba="0.79216 0.81961 0.93333 1" />
      </material>
    </visual>
    <collision>
      <origin rpy="${pi/2.0} 0 0" xyz="0.0 -0.05 0" />
      <geometry>
        <!-- <box size="0.05 0.03 0.3"/> -->
        <cylinder length="0.06" radius="0.05" />
      </geometry>
    </collision>
  </link>
  <joint name="LF_HAA" type="revolute">
    <origin rpy="3.141592653589793 0.0 0 " xyz="0.2467 0.09 0" />
    <parent link="base" />
    <child link="LF_hip" />
    <axis xyz="1 0 0" />
    <limit effort="55" lower="-1.0" upper="1.0" velocity="30" />
  </joint>
  <link name="LF_thigh">
    <inertial>
      <origin rpy="0 0 0" xyz="-2.7705E-05 -0.089684 -0.23198" />
      <mass value="1.556" />
      <inertia ixx="0.015631" ixy="-8.61E-07" ixz="-6.078E-06" iyy="0.016183" iyz="0.0004689"
        izz="0.0011163" />
    </inertial>
    <visual>
      <origin rpy="0 0 0" xyz="0 0 0" />
      <geometry>
        <mesh filename="package://lion_arx3_description/meshes/thigh_Link.STL" />
      </geometry>
      <material name="">
        <color rgba="0.79216 0.81961 0.93333 1" />
      </material>
    </visual>
    <collision>
      <origin rpy="${pi/2.0} 0 0" xyz="0 -0.09 -0.3" />
      <geometry>
        <!-- <box size="0.05 0.03 0.3"/> -->
        <cylinder length="0.06" radius="0.05" />
      </geometry>
    </collision>
  </link>
  <joint name="LF_HFE" type="revolute">
    <origin rpy="0 3.141592653589793 0" xyz="0 0 0" />
    <parent link="LF_hip" />
    <child link="LF_thigh" />
    <axis xyz="0 -1 0" />
    <limit effort="55" lower="-3.0" upper="3.0" velocity="30" />
  </joint>
  <link name="LF_calf">
    <inertial>
      <origin rpy="0 0 0" xyz="2.05E-06 -0.12517 -0.080832" />
      <mass value="0.233" />
      <inertia ixx="0.0033053" ixy="-3.64E-07" ixz="4.028E-06" iyy="0.0033126" iyz="-0.00013194"
        izz="4.3236E-05" />
    </inertial>
    <visual>
      <origin rpy="0 0 0" xyz="0 0 0" />
      <geometry>
        <mesh filename="package://lion_arx3_description/meshes/shank_Link.STL" />
      </geometry>
      <material name="">
        <color rgba="0.79216 0.81961 0.93333 1" />
      </material>
    </visual>
    <collision>
      <origin rpy="0 0 0" xyz="0 -0.119 -0.15" />
      <geometry>
        <cylinder length="0.2" radius="0.01" />
      </geometry>
    </collision>
  </link>
  <joint name="LF_KFE" type="revolute">
    <origin rpy="0 0 0" xyz="0 0 -0.3" />
    <parent link="LF_thigh" />
    <child link="LF_calf" />
    <axis xyz="0 -1 0" />
    <limit effort="55" lower="-3.0" upper="-0.5" velocity="30" />
  </joint>
  <link name="LF_FOOT">
    <contact>
      <friction_anchor />
      <stiffness value="30000.0" />
      <damping value="1000.0" />
      <spinning_friction value="0.3" />
      <lateral_friction value="3.0" />
    </contact>
    <inertial>
      <origin rpy="0 0 0" xyz="0.0002617 0.00017365 0.0085579" />
      <!-- <mass value="0.03946"/> -->
      <mass value="0.01" />
      <!-- <inertia ixx="1.4527E-05" ixy="-8.5021E-08" ixz="-4.0103E-07" iyy="1.4601E-05"
      iyz="-2.6548E-07" izz="6.2338E-06"/> -->
      <inertia ixx="0.001983" ixy="0.000245" ixz="0.000013"
        iyy="0.002103" iyz="0.0000015" izz="0.000408" />
    </inertial>
    <visual>
      <origin rpy="0 0 0" xyz="0 0 0" />
      <geometry>
        <mesh filename="package://lion_arx3_description/meshes/foot_Link.STL" />
      </geometry>
      <material name="">
        <color rgba="0.79216 0.81961 0.93333 1" />
      </material>
    </visual>
    <collision>
      <origin rpy="0 0 0" xyz="0 0 0.002" />
      <geometry>
        <sphere radius="0.02" />
      </geometry>
    </collision>
  </link>
  <joint name="JointFL_foot" type="fixed">
    <origin rpy="0 0 0" xyz="0 -0.119 -0.3105" />
    <parent link="LF_calf" />
    <child link="LF_FOOT" />
    <axis xyz="0 0 1" />

  </joint>
  <link name="RH_hip">
    <inertial>
      <origin rpy="0 0 0" xyz="-0.0050797 -0.047183 4.172E-05" />
      <mass value="1.095" />
      <inertia ixx="0.0010035" ixy="-0.00021789" ixz="1.433E-06" iyy="0.0014762" iyz="1.005E-06"
        izz="0.0012507" />
    </inertial>
    <visual>
      <origin rpy="0 0 0" xyz="0 0 0" />
      <geometry>
        <mesh filename="package://lion_arx3_description/meshes/hip_Link.STL" />
      </geometry>
      <material name="">
        <color rgba="0.79216 0.81961 0.93333 1" />
      </material>
    </visual>
    <collision>
      <origin rpy="${pi/2.0} 0 0" xyz="0.0 -0.05 0" />
      <geometry>
        <!-- <box size="0.05 0.03 0.3"/> -->
        <cylinder length="0.06" radius="0.05" />
      </geometry>
    </collision>
  </link>
  <joint name="RH_HAA" type="revolute">
    <origin rpy="0.0 3.141592653589793 0 " xyz="-0.2467 -0.09 0" />
    <parent link="base" />
    <child link="RH_hip" />
    <axis xyz="-1 0 0" />
    <limit effort="55" lower="-1.0" upper="1.0" velocity="30" />
  </joint>
  <link name="RH_thigh">
    <inertial>
      <origin rpy="0 0 0" xyz="-2.7705E-05 -0.089684 -0.23198" />
      <mass value="1.556" />
      <inertia ixx="0.015631" ixy="-8.61E-07" ixz="-6.078E-06" iyy="0.016183" iyz="0.0004689"
        izz="0.0011163" />
    </inertial>
    <visual>
      <origin rpy="0 0 0" xyz="0 0 0" />
      <geometry>
        <mesh filename="package://lion_arx3_description/meshes/thigh_Link.STL" />
      </geometry>
      <material name="">
        <color rgba="0.79216 0.81961 0.93333 1" />
      </material>
    </visual>
    <collision>
      <origin rpy="${pi/2.0} 0 0" xyz="0 -0.09 -0.3" />
      <geometry>
        <!-- <box size="0.05 0.03 0.3"/> -->
        <cylinder length="0.06" radius="0.05" />
      </geometry>
    </collision>
  </link>
  <joint name="RH_HFE" type="revolute">
    <origin rpy="0 3.141592653589793 0" xyz="0 0 0" />
    <parent link="RH_hip" />
    <child link="RH_thigh" />
    <axis xyz="0 1 0" />
    <limit effort="55" lower="-3.0" upper="3.0" velocity="30" />
  </joint>
  <link name="RH_calf">
    <inertial>
      <origin rpy="0 0 0" xyz="2.05E-06 -0.12517 -0.080832" />
      <mass value="0.233" />
      <inertia ixx="0.0033053" ixy="-3.64E-07" ixz="4.028E-06" iyy="0.0033126" iyz="-0.00013194"
        izz="4.3236E-05" />
    </inertial>
    <visual>
      <origin rpy="0 0 0" xyz="0 0 0" />
      <geometry>
        <mesh filename="package://lion_arx3_description/meshes/shank_Link.STL" />
      </geometry>
      <material name="">
        <color rgba="0.79216 0.81961 0.93333 1" />
      </material>
    </visual>
    <collision>
      <origin rpy="0 0 0" xyz="0 -0.119 -0.15" />
      <geometry>
        <cylinder length="0.2" radius="0.01" />
      </geometry>
    </collision>
  </link>
  <joint name="RH_KFE" type="revolute">
    <origin rpy="0 0 0" xyz="0 0 -0.3" />
    <parent link="RH_thigh" />
    <child link="RH_calf" />
    <axis xyz="0 1 0" />
    <limit effort="55" lower="-3.0" upper="-0.5" velocity="30" />
  </joint>
  <link name="RH_FOOT">
    <contact>
      <friction_anchor />
      <stiffness value="30000.0" />
      <damping value="1000.0" />
      <spinning_friction value="0.3" />
      <lateral_friction value="3.0" />
    </contact>
    <inertial>
      <origin rpy="0 0 0" xyz="0.0002617 0.00017365 0.0085579" />
      <!-- <mass value="0.03946"/> -->
      <mass value="0.01" />
      <!-- <inertia ixx="1.4527E-05" ixy="-8.5021E-08" ixz="-4.0103E-07" iyy="1.4601E-05"
      iyz="-2.6548E-07" izz="6.2338E-06"/> -->
      <inertia ixx="0.001983" ixy="0.000245" ixz="0.000013"
        iyy="0.002103" iyz="0.0000015" izz="0.000408" />
    </inertial>
    <visual>
      <origin rpy="0 0 0" xyz="0 0 0" />
      <geometry>
        <mesh filename="package://lion_arx3_description/meshes/foot_Link.STL" />
      </geometry>
      <material name="">
        <color rgba="0.79216 0.81961 0.93333 1" />
      </material>
    </visual>
    <collision>
      <origin rpy="0 0 0" xyz="0 0 0.002" />
      <geometry>
        <sphere radius="0.02" />
      </geometry>
    </collision>
  </link>
  <joint name="JointHR_foot" type="fixed">
    <origin rpy="0 0 0" xyz="0 -0.119 -0.3105" />
    <parent link="RH_calf" />
    <child link="RH_FOOT" />
    <axis xyz="0 0 1" />

  </joint>
  <link name="LH_hip">
    <inertial>
      <origin rpy="0 0 0" xyz="-0.0050797 -0.047183 4.172E-05" />
      <mass value="1.095" />
      <inertia ixx="0.0010035" ixy="-0.00021789" ixz="1.433E-06" iyy="0.0014762" iyz="1.005E-06"
        izz="0.0012507" />
    </inertial>
    <visual>
      <origin rpy="0 0 0" xyz="0 0 0" />
      <geometry>
        <mesh filename="package://lion_arx3_description/meshes/hip_Link.STL" />
      </geometry>
      <material name="">
        <color rgba="0.79216 0.81961 0.93333 1" />
      </material>
    </visual>
    <collision>
      <origin rpy="${pi/2.0} 0 0" xyz="0.0 -0.05 0" />
      <geometry>
        <!-- <box size="0.05 0.03 0.3"/> -->
        <cylinder length="0.06" radius="0.05" />
      </geometry>
    </collision>
  </link>
  <joint name="LH_HAA" type="revolute">
    <origin rpy="3.141592653589793 3.141592653589793 0 " xyz="-0.2467 0.09 0" />
    <parent link="base" />
    <child link="LH_hip" />
    <axis xyz="-1 0 0" />
    <limit effort="55" lower="-1.0" upper="1.0" velocity="30" />
  </joint>
  <link name="LH_thigh">
    <inertial>
      <origin rpy="0 0 0" xyz="-2.7705E-05 -0.089684 -0.23198" />
      <mass value="1.556" />
      <inertia ixx="0.015631" ixy="-8.61E-07" ixz="-6.078E-06" iyy="0.016183" iyz="0.0004689"
        izz="0.0011163" />
    </inertial>
    <visual>
      <origin rpy="0 0 0" xyz="0 0 0" />
      <geometry>
        <mesh filename="package://lion_arx3_description/meshes/thigh_Link.STL" />
      </geometry>
      <material name="">
        <color rgba="0.79216 0.81961 0.93333 1" />
      </material>
    </visual>
    <collision>
      <origin rpy="${pi/2.0} 0 0" xyz="0 -0.09 -0.3" />
      <geometry>
        <!-- <box size="0.05 0.03 0.3"/> -->
        <cylinder length="0.06" radius="0.05" />
      </geometry>
    </collision>
  </link>
  <joint name="LH_HFE" type="revolute">
    <origin rpy="0 6.283185307179586 0" xyz="0 0 0" />
    <parent link="LH_hip" />
    <child link="LH_thigh" />
    <axis xyz="0 -1 0" />
    <limit effort="55" lower="-3.0" upper="3.0" velocity="30" />
  </joint>
  <link name="LH_calf">
    <inertial>
      <origin rpy="0 0 0" xyz="2.05E-06 -0.12517 -0.080832" />
      <mass value="0.233" />
      <inertia ixx="0.0033053" ixy="-3.64E-07" ixz="4.028E-06" iyy="0.0033126" iyz="-0.00013194"
        izz="4.3236E-05" />
    </inertial>
    <visual>
      <origin rpy="0 0 0" xyz="0 0 0" />
      <geometry>
        <mesh filename="package://lion_arx3_description/meshes/shank_Link.STL" />
      </geometry>
      <material name="">
        <color rgba="0.79216 0.81961 0.93333 1" />
      </material>
    </visual>
    <collision>
      <origin rpy="0 0 0" xyz="0 -0.119 -0.15" />
      <geometry>
        <cylinder length="0.2" radius="0.01" />
      </geometry>
    </collision>
  </link>
  <joint name="LH_KFE" type="revolute">
    <origin rpy="0 0 0" xyz="0 0 -0.3" />
    <parent link="LH_thigh" />
    <child link="LH_calf" />
    <axis xyz="0 -1 0" />
    <limit effort="55" lower="-3.0" upper="-0.5" velocity="30" />
  </joint>
  <link name="LH_FOOT">
    <contact>
      <friction_anchor />
      <stiffness value="30000.0" />
      <damping value="1000.0" />
      <spinning_friction value="0.3" />
      <lateral_friction value="3.0" />
    </contact>
    <inertial>
      <origin rpy="0 0 0" xyz="0.0002617 0.00017365 0.0085579" />
      <!-- <mass value="0.03946"/> -->
      <mass value="0.01" />
      <!-- <inertia ixx="1.4527E-05" ixy="-8.5021E-08" ixz="-4.0103E-07" iyy="1.4601E-05"
      iyz="-2.6548E-07" izz="6.2338E-06"/> -->
      <inertia ixx="0.001983" ixy="0.000245" ixz="0.000013"
        iyy="0.002103" iyz="0.0000015" izz="0.000408" />
    </inertial>
    <visual>
      <origin rpy="0 0 0" xyz="0 0 0" />
      <geometry>
        <mesh filename="package://lion_arx3_description/meshes/foot_Link.STL" />
      </geometry>
      <material name="">
        <color rgba="0.79216 0.81961 0.93333 1" />
      </material>
    </visual>
    <collision>
      <origin rpy="0 0 0" xyz="0 0 0.002" />
      <geometry>
        <sphere radius="0.02" />
      </geometry>
    </collision>
  </link>
  <joint name="JointHL_foot" type="fixed">
    <origin rpy="0 0 0" xyz="0 -0.119 -0.3105" />
    <parent link="LH_calf" />
    <child link="LH_FOOT" />
    <axis xyz="0 0 1" />

  </joint>
  <!-- Arm Model
  ********************************************************************************************************  -->
  <link name="arm_base_link">
    <inertial>
      <origin
        xyz="-2.9956E-05 3.0541E-05 0.027289"
        rpy="0 0 0" />
      <mass
        value="0.44061" />
      <inertia
        ixx="0.00017"
        ixy="0.00000"
        ixz="0.00000"
        iyy="0.00018"
        iyz="0.00000"
        izz="0.00016" />
    </inertial>
    <visual>
      <origin
        xyz="0 0 0"
        rpy="0 0 0" />
      <geometry>
        <mesh
          filename="package://lion_arx3_description/meshes/arm_base_link.STL" />
      </geometry>
      <material
        name="">
        <color
          rgba="0.75294 0.75294 0.75294 1" />
      </material>
    </visual>
    <collision>
      <origin rpy="0 0 0" xyz="0 0.0 0.03" />
      <geometry>
        <!-- <box size="0.05 0.03 0.3"/> -->
        <cylinder length="0.05" radius="0.03" />
      </geometry>
    </collision>
  </link>
  <joint name="arm_fix" type="fixed">
    <origin
      xyz="0.1075 0 0.0635"
      rpy="0 0 0" />
    <parent
      link="base" />
    <child
      link="arm_base_link" />
  </joint>
  <link name="shoulder_link">
    <inertial>
      <origin
        xyz="-0.00012207 -6.5868E-06 0.016529"
        rpy="0 0 0" />
      <mass
        value="0.078442" />
      <inertia
        ixx="0.00009"
        ixy="0.00000"
        ixz="0.00000"
        iyy="0.00003"
        iyz="0.00000"
        izz="0.00009" />
    </inertial>
    <visual>
      <origin
        xyz="0 0 0"
        rpy="0 0 0" />
      <geometry>
        <mesh
          filename="package://lion_arx3_description/meshes/link1.STL" />
      </geometry>
      <material
        name="">
        <color
          rgba="0.75294 0.75294 0.75294 1" />
      </material>
    </visual>
    <collision>
      <origin
        xyz="0 0 0"
        rpy="0 0 0" />
      <geometry>
        <cylinder length="0.01" radius="0.03" />
      </geometry>
    </collision>
  </link>
  <joint name="joint1"
    type="revolute">
    <origin
      xyz="0 0 0.0603"
      rpy="0 0 0" />
    <parent
      link="arm_base_link" />
    <child
      link="shoulder_link" />
    <axis
      xyz="0 0 1" />
    <limit
      lower="-1.57"
      upper="1.57"
      effort="25.0"
      velocity="10.0" />
    <dynamics damping="0.1" friction="0.01"/>
  </joint>
  <link name="upper_arm_link">
    <inertial>
      <origin
        xyz="-0.13238 0.0021952 0.00011182"
        rpy="0 0 0" />
      <mass
        value="1.073" />
      <inertia
        ixx="0.00050"
        ixy="0.00000"
        ixz="-0.00004"
        iyy="0.01596"
        iyz="0.00000"
        izz="0.01602" />
    </inertial>
    <visual>
      <origin
        xyz="0 0 0"
        rpy="0 0 0" />
      <geometry>
        <mesh
          filename="package://lion_arx3_description/meshes/link2.STL" />
      </geometry>
      <material
        name="">
        <color
          rgba="0.75294 0.75294 0.75294 1" />
      </material>
    </visual>
    <collision>
      <origin rpy="0 ${pi/2.0} 0" xyz="-0.14 0.0 0.0" />
      <geometry>
        <!-- <box size="0.05 0.03 0.3"/> -->
        <cylinder length="0.28" radius="0.025" />
      </geometry>
    </collision>
  </link>
  <joint name="joint2"
    type="revolute">
    <origin
      xyz="0 0 0.0402"
      rpy="0 0 0" />
    <parent
      link="shoulder_link" />
    <child
      link="upper_arm_link" />
    <axis
      xyz="0 1 0" />
    <limit
      lower="0."
      upper="3.14"
      effort="25.0"
      velocity="10." />
    <dynamics damping="0.1" friction="0.01"/>
  </joint>
  <link name="elbow_link">
    <inertial>
      <origin
        xyz="0.18794 0.0016321 -0.051557"
        rpy="0 0 0" />
      <mass
        value="0.50518" />
      <inertia
        ixx="0.00037"
        ixy="-0.00001"
        ixz="-0.00039"
        iyy="0.00393"
        iyz="0.00001"
        izz="0.00390" />
    </inertial>
    <visual>
      <origin
        xyz="0 0 0"
        rpy="0 0 0" />
      <geometry>
        <mesh
          filename="package://lion_arx3_description/meshes/link3.STL" />
      </geometry>
      <material
        name="">
        <color
          rgba="0.75294 0.75294 0.75294 1" />
      </material>
    </visual>
    <collision>
      <origin rpy="0 ${pi/2.0} 0" xyz="0.15 0.0 -0.055" />
      <geometry>
        <!-- <box size="0.05 0.03 0.3"/> -->
        <cylinder length="0.2" radius="0.02" />
      </geometry>
    </collision>
  </link>
  <joint name="joint3"
    type="revolute">
    <origin
      xyz="-0.264 0 0"
      rpy="-3.1416 0 0" />
    <parent
      link="upper_arm_link" />
    <child
      link="elbow_link" />
    <axis
      xyz="0 1 0" />
    <limit
      lower="0.05"
      upper="3.14"
      effort="25."
      velocity="10." />
    <dynamics damping="0.1" friction="0.01"/>
  </joint>
  <link name="lower_arm_link">
    <inertial>
      <origin
        xyz="0.054496 -0.00085704 0.0020301"
        rpy="0 0 0" />
      <mass
        value="0.34332" />
      <inertia
        ixx="0.00018"
        ixy="-0.00001"
        ixz="0.00000"
        iyy="0.00022"
        iyz="0.00001"
        izz="0.00026" />
    </inertial>
    <visual>
      <origin
        xyz="0 0 0"
        rpy="0 0 0" />
      <geometry>
        <mesh
          filename="package://lion_arx_description/meshes/link4.STL" />
      </geometry>
      <material
        name="">
        <color
          rgba="0.75294 0.75294 0.75294 1" />
      </material>
    </visual>
    <collision>
      <origin rpy="${pi/2.0} 0 0" xyz="0.06 0.0 -0.0" />
      <geometry>
        <!-- <box size="0.05 0.03 0.3"/> -->
        <cylinder length="0.06" radius="0.025" />
      </geometry>
    </collision>
  </link>
  <joint name="joint4"
    type="fixed">
    <origin
      xyz="0.245 0 -0.056"
      rpy="0 0 0" />
    <parent
      link="elbow_link" />
    <child
      link="lower_arm_link" />
    <axis
      xyz="0 1 0" />
  </joint>


  <xacro:IMU connected_to="base" imu_name="unitree_imu" xyz="0. 0. 0." rpy="0. 0. 0." />
  <xacro:leg_transmission prefix="RF" />
  <xacro:leg_transmission prefix="LF" />
  <xacro:leg_transmission prefix="RH" />
  <xacro:leg_transmission prefix="LH" />

  <xacro:arm_transmission num="1" />
  <xacro:arm_transmission num="2" />
  <xacro:arm_transmission num="3" />



</robot>